[36mATRI[0m | 03-03 11:03:12 | WARNING nonebot >> Duplicated prefix rule "!lottery"
[36mATRI[0m | 03-03 11:03:12 | WARNING nonebot >> Duplicated prefix rule "/lottery"
[36mATRI[0m | 03-03 11:03:12 | WARNING nonebot >> Duplicated prefix rule "！lottery"
[36mATRI[0m | 03-03 11:03:12 | ERROR plugin.manager >> Failed to import "nonebot_plugin_statistical"
Traceback (most recent call last):

  File "/usr/bin/nb", line 8, in <module>
    sys.exit(main())
    │   │    └ <ClickAliasedGroup main>
    │   └ <built-in function exit>
    └ <module 'sys' (built-in)>
  File "/usr/local/python3/lib/python3.8/site-packages/click/core.py", line 1128, in __call__
    return self.main(*args, **kwargs)
           │    │     │       └ {}
           │    │     └ ()
           │    └ <function BaseCommand.main at 0x7f438c7a7040>
           └ <ClickAliasedGroup main>
  File "/usr/local/python3/lib/python3.8/site-packages/click/core.py", line 1053, in main
    rv = self.invoke(ctx)
         │    │      └ <click.core.Context object at 0x7f439491b130>
         │    └ <function MultiCommand.invoke at 0x7f438c7ab0d0>
         └ <ClickAliasedGroup main>
  File "/usr/local/python3/lib/python3.8/site-packages/click/core.py", line 1659, in invoke
    return _process_result(sub_ctx.command.invoke(sub_ctx))
           │               │       │       │      └ <click.core.Context object at 0x7f4394920ca0>
           │               │       │       └ <function Command.invoke at 0x7f438c7a7af0>
           │               │       └ <ClickAliasedCommand run>
           │               └ <click.core.Context object at 0x7f4394920ca0>
           └ <function MultiCommand.invoke.<locals>._process_result at 0x7f438cff4a60>
  File "/usr/local/python3/lib/python3.8/site-packages/click/core.py", line 1395, in invoke
    return ctx.invoke(self.callback, **ctx.params)
           │   │      │    │           │   └ {'file': 'bot.py', 'app': 'app'}
           │   │      │    │           └ <click.core.Context object at 0x7f4394920ca0>
           │   │      │    └ <function run at 0x7f43837f35e0>
           │   │      └ <ClickAliasedCommand run>
           │   └ <function Context.invoke at 0x7f438ca248b0>
           └ <click.core.Context object at 0x7f4394920ca0>
  File "/usr/local/python3/lib/python3.8/site-packages/click/core.py", line 754, in invoke
    return __callback(*args, **kwargs)
                       │       └ {'file': 'bot.py', 'app': 'app'}
                       └ ()
  File "/usr/local/python3/lib/python3.8/site-packages/nb_cli/commands/main.py", line 30, in run
    run_bot(file, app)
    │       │     └ 'app'
    │       └ 'bot.py'
    └ <function run_bot at 0x7f43837e33a0>
  File "/usr/local/python3/lib/python3.8/site-packages/nb_cli/handlers/deploy.py", line 19, in run_bot
    module = importlib.import_module(module_name)
             │         │             └ 'bot'
             │         └ <function import_module at 0x7f439495b8b0>
             └ <module 'importlib' from '/usr/local/python3/lib/python3.8/importlib/__init__.py'>
  File "/usr/local/python3/lib/python3.8/importlib/__init__.py", line 127, in import_module
    return _bootstrap._gcd_import(name[level:], package, level)
           │          │           │    │        │        └ 0
           │          │           │    │        └ None
           │          │           │    └ 0
           │          │           └ 'bot'
           │          └ <function _gcd_import at 0x7f4394a8a430>
           └ <module 'importlib._bootstrap' (frozen)>
  File "<frozen importlib._bootstrap>", line 1014, in _gcd_import
  File "<frozen importlib._bootstrap>", line 991, in _find_and_load
  File "<frozen importlib._bootstrap>", line 975, in _find_and_load_unlocked
  File "<frozen importlib._bootstrap>", line 671, in _load_unlocked
  File "<frozen importlib._bootstrap_external>", line 783, in exec_module
  File "<frozen importlib._bootstrap>", line 219, in _call_with_frames_removed

  File "./bot.py", line 29, in <module>
    nonebot.load_plugins("src/plugins")
    │       └ <function load_plugins at 0x7f438a6233a0>
    └ <module 'nonebot' from '/usr/local/python3/lib/python3.8/site-packages/nonebot/__init__.py'>

  File "/usr/local/python3/lib/python3.8/site-packages/nonebot/plugin/load.py", line 39, in load_plugins
    return manager.load_all_plugins()
           │       └ <function PluginManager.load_all_plugins at 0x7f438a614ee0>
           └ <nonebot.plugin.manager.PluginManager object at 0x7f4382fd7c10>
  File "/usr/local/python3/lib/python3.8/site-packages/nonebot/plugin/manager.py", line 128, in load_all_plugins
    return set(
  File "/usr/local/python3/lib/python3.8/site-packages/nonebot/plugin/manager.py", line 129, in <genexpr>
    filter(None, (self.load_plugin(name) for name in self.list_plugins()))
                  │    │           │         │       │    └ <function PluginManager.list_plugins at 0x7f438a614dc0>
                  │    │           │         │       └ <nonebot.plugin.manager.PluginManager object at 0x7f4382fd7c10>
                  │    │           │         └ 'nonebot_plugin_statistical'
                  │    │           └ 'nonebot_plugin_statistical'
                  │    └ <function PluginManager.load_plugin at 0x7f438a614e50>
                  └ <nonebot.plugin.manager.PluginManager object at 0x7f4382fd7c10>
> File "/usr/local/python3/lib/python3.8/site-packages/nonebot/plugin/manager.py", line 106, in load_plugin
    module = importlib.import_module(
             │         └ <function import_module at 0x7f439495b8b0>
             └ <module 'importlib' from '/usr/local/python3/lib/python3.8/importlib/__init__.py'>
  File "/usr/local/python3/lib/python3.8/importlib/__init__.py", line 127, in import_module
    return _bootstrap._gcd_import(name[level:], package, level)
           │          │           │    │        │        └ 0
           │          │           │    │        └ None
           │          │           │    └ 0
           │          │           └ 'src.plugins.nonebot_plugin_statistical'
           │          └ <function _gcd_import at 0x7f4394a8a430>
           └ <module 'importlib._bootstrap' (frozen)>
  File "<frozen importlib._bootstrap>", line 1014, in _gcd_import
  File "<frozen importlib._bootstrap>", line 991, in _find_and_load
  File "<frozen importlib._bootstrap>", line 975, in _find_and_load_unlocked
  File "<frozen importlib._bootstrap>", line 671, in _load_unlocked
  File "/usr/local/python3/lib/python3.8/site-packages/nonebot/plugin/manager.py", line 194, in exec_module
    super().exec_module(module)
                        └ <module 'src.plugins.nonebot_plugin_statistical' from './src/plugins/nonebot_plugin_statistical/__init__.py'>
  File "<frozen importlib._bootstrap_external>", line 783, in exec_module
  File "<frozen importlib._bootstrap>", line 219, in _call_with_frames_removed

  File "./src/plugins/nonebot_plugin_statistical/__init__.py", line 1, in <module>
    from .statistical_hook import *

  File "./src/plugins/nonebot_plugin_statistical/statistical_hook.py", line 7, in <module>
    from .config import save_data, get_prefix_group_count_dict, get_prefix_user_count_dict, \

  File "./src/plugins/nonebot_plugin_statistical/config.py", line 149, in <module>
    plugin2cmd: dict = json.load(f)
                       │    │    └ <_io.TextIOWrapper name='/root/Projects/Kori-Bot/Kori-bot/data/statistical/plugin2cmd.json' mode='r' encoding='utf8'>
                       │    └ <built-in function load>
                       └ <module 'ujson' from '/usr/local/python3/lib/python3.8/site-packages/ujson.cpython-38-x86_64-linux-gnu.so'>

ValueError: Expected object or value
[36mATRI[0m | 03-03 11:03:13 | ERROR plugin.manager >> Failed to import "whitenight_from_feiyucans_space"
Traceback (most recent call last):

  File "/usr/bin/nb", line 8, in <module>
    sys.exit(main())
    │   │    └ <ClickAliasedGroup main>
    │   └ <built-in function exit>
    └ <module 'sys' (built-in)>
  File "/usr/local/python3/lib/python3.8/site-packages/click/core.py", line 1128, in __call__
    return self.main(*args, **kwargs)
           │    │     │       └ {}
           │    │     └ ()
           │    └ <function BaseCommand.main at 0x7f438c7a7040>
           └ <ClickAliasedGroup main>
  File "/usr/local/python3/lib/python3.8/site-packages/click/core.py", line 1053, in main
    rv = self.invoke(ctx)
         │    │      └ <click.core.Context object at 0x7f439491b130>
         │    └ <function MultiCommand.invoke at 0x7f438c7ab0d0>
         └ <ClickAliasedGroup main>
  File "/usr/local/python3/lib/python3.8/site-packages/click/core.py", line 1659, in invoke
    return _process_result(sub_ctx.command.invoke(sub_ctx))
           │               │       │       │      └ <click.core.Context object at 0x7f4394920ca0>
           │               │       │       └ <function Command.invoke at 0x7f438c7a7af0>
           │               │       └ <ClickAliasedCommand run>
           │               └ <click.core.Context object at 0x7f4394920ca0>
           └ <function MultiCommand.invoke.<locals>._process_result at 0x7f438cff4a60>
  File "/usr/local/python3/lib/python3.8/site-packages/click/core.py", line 1395, in invoke
    return ctx.invoke(self.callback, **ctx.params)
           │   │      │    │           │   └ {'file': 'bot.py', 'app': 'app'}
           │   │      │    │           └ <click.core.Context object at 0x7f4394920ca0>
           │   │      │    └ <function run at 0x7f43837f35e0>
           │   │      └ <ClickAliasedCommand run>
           │   └ <function Context.invoke at 0x7f438ca248b0>
           └ <click.core.Context object at 0x7f4394920ca0>
  File "/usr/local/python3/lib/python3.8/site-packages/click/core.py", line 754, in invoke
    return __callback(*args, **kwargs)
                       │       └ {'file': 'bot.py', 'app': 'app'}
                       └ ()
  File "/usr/local/python3/lib/python3.8/site-packages/nb_cli/commands/main.py", line 30, in run
    run_bot(file, app)
    │       │     └ 'app'
    │       └ 'bot.py'
    └ <function run_bot at 0x7f43837e33a0>
  File "/usr/local/python3/lib/python3.8/site-packages/nb_cli/handlers/deploy.py", line 19, in run_bot
    module = importlib.import_module(module_name)
             │         │             └ 'bot'
             │         └ <function import_module at 0x7f439495b8b0>
             └ <module 'importlib' from '/usr/local/python3/lib/python3.8/importlib/__init__.py'>
  File "/usr/local/python3/lib/python3.8/importlib/__init__.py", line 127, in import_module
    return _bootstrap._gcd_import(name[level:], package, level)
           │          │           │    │        │        └ 0
           │          │           │    │        └ None
           │          │           │    └ 0
           │          │           └ 'bot'
           │          └ <function _gcd_import at 0x7f4394a8a430>
           └ <module 'importlib._bootstrap' (frozen)>
  File "<frozen importlib._bootstrap>", line 1014, in _gcd_import
  File "<frozen importlib._bootstrap>", line 991, in _find_and_load
  File "<frozen importlib._bootstrap>", line 975, in _find_and_load_unlocked
  File "<frozen importlib._bootstrap>", line 671, in _load_unlocked
  File "<frozen importlib._bootstrap_external>", line 783, in exec_module
  File "<frozen importlib._bootstrap>", line 219, in _call_with_frames_removed

  File "./bot.py", line 29, in <module>
    nonebot.load_plugins("src/plugins")
    │       └ <function load_plugins at 0x7f438a6233a0>
    └ <module 'nonebot' from '/usr/local/python3/lib/python3.8/site-packages/nonebot/__init__.py'>

  File "/usr/local/python3/lib/python3.8/site-packages/nonebot/plugin/load.py", line 39, in load_plugins
    return manager.load_all_plugins()
           │       └ <function PluginManager.load_all_plugins at 0x7f438a614ee0>
           └ <nonebot.plugin.manager.PluginManager object at 0x7f4382fd7c10>
  File "/usr/local/python3/lib/python3.8/site-packages/nonebot/plugin/manager.py", line 128, in load_all_plugins
    return set(
  File "/usr/local/python3/lib/python3.8/site-packages/nonebot/plugin/manager.py", line 129, in <genexpr>
    filter(None, (self.load_plugin(name) for name in self.list_plugins()))
                  │    │           │         │       │    └ <function PluginManager.list_plugins at 0x7f438a614dc0>
                  │    │           │         │       └ <nonebot.plugin.manager.PluginManager object at 0x7f4382fd7c10>
                  │    │           │         └ 'whitenight_from_feiyucans_space'
                  │    │           └ 'whitenight_from_feiyucans_space'
                  │    └ <function PluginManager.load_plugin at 0x7f438a614e50>
                  └ <nonebot.plugin.manager.PluginManager object at 0x7f4382fd7c10>
> File "/usr/local/python3/lib/python3.8/site-packages/nonebot/plugin/manager.py", line 106, in load_plugin
    module = importlib.import_module(
             │         └ <function import_module at 0x7f439495b8b0>
             └ <module 'importlib' from '/usr/local/python3/lib/python3.8/importlib/__init__.py'>
  File "/usr/local/python3/lib/python3.8/importlib/__init__.py", line 127, in import_module
    return _bootstrap._gcd_import(name[level:], package, level)
           │          │           │    │        │        └ 0
           │          │           │    │        └ None
           │          │           │    └ 0
           │          │           └ 'src.plugins.whitenight_from_feiyucans_space'
           │          └ <function _gcd_import at 0x7f4394a8a430>
           └ <module 'importlib._bootstrap' (frozen)>
  File "<frozen importlib._bootstrap>", line 1014, in _gcd_import
  File "<frozen importlib._bootstrap>", line 991, in _find_and_load
  File "<frozen importlib._bootstrap>", line 975, in _find_and_load_unlocked
  File "<frozen importlib._bootstrap>", line 671, in _load_unlocked
  File "/usr/local/python3/lib/python3.8/site-packages/nonebot/plugin/manager.py", line 194, in exec_module
    super().exec_module(module)
                        └ <module 'src.plugins.whitenight_from_feiyucans_space' from './src/plugins/whitenight_from_feiyucans_space/__init__.py'>
  File "<frozen importlib._bootstrap_external>", line 783, in exec_module
  File "<frozen importlib._bootstrap>", line 219, in _call_with_frames_removed

  File "./src/plugins/whitenight_from_feiyucans_space/__init__.py", line 78, in <module>
    scheduler.add_job(whitenight, "cron", hour=22, minute=30, id=146487)
    │         │       └ <function whitenight at 0x7f43624e8e50>
    │         └ <function BaseScheduler.add_job at 0x7f437a6c73a0>
    └ <apscheduler.schedulers.asyncio.AsyncIOScheduler object at 0x7f437a9bc2e0>

  File "/usr/local/python3/lib/python3.8/site-packages/apscheduler/schedulers/base.py", line 439, in add_job
    job = Job(self, **job_kwargs)
          │   │       └ {'trigger': <CronTrigger (hour='22', minute='30', timezone='Asia/Shanghai')>, 'executor': 'default', 'func': <function whiten...
          │   └ <apscheduler.schedulers.asyncio.AsyncIOScheduler object at 0x7f437a9bc2e0>
          └ <class 'apscheduler.job.Job'>
  File "/usr/local/python3/lib/python3.8/site-packages/apscheduler/job.py", line 49, in __init__
    self._modify(id=id or uuid4().hex, **kwargs)
    │    │          │     │              └ {'trigger': <CronTrigger (hour='22', minute='30', timezone='Asia/Shanghai')>, 'executor': 'default', 'func': <function whiten...
    │    │          │     └ <function uuid4 at 0x7f4389dc4f70>
    │    │          └ 146487
    │    └ <function Job._modify at 0x7f437a739a60>
    └ <unprintable Job object>
  File "/usr/local/python3/lib/python3.8/site-packages/apscheduler/job.py", line 150, in _modify
    raise TypeError("id must be a nonempty string")

TypeError: id must be a nonempty string
[36mATRI[0m | 03-03 11:19:55 | WARNING nonebot >> OneBot V11 | WebSocket for Bot 507346814 closed by peer
[36mATRI[0m | 03-03 11:22:55 | WARNING nonebot >> OneBot V11 | WebSocket for Bot 507346814 closed by peer
[36mATRI[0m | 03-03 11:23:02 | WARNING nonebot >> Duplicated prefix rule "!lottery"
[36mATRI[0m | 03-03 11:23:02 | WARNING nonebot >> Duplicated prefix rule "！lottery"
[36mATRI[0m | 03-03 11:23:02 | WARNING nonebot >> Duplicated prefix rule "/lottery"
[36mATRI[0m | 03-03 11:55:25 | WARNING nonebot >> OneBot V11 | WebSocket for Bot 507346814 closed by peer
[36mATRI[0m | 03-03 15:09:38 | ERROR nonebot >> Running matcher <Matcher from src.plugins.nonebot_plugin_russian, type=message, priority=5, temp=False> failed.
Traceback (most recent call last):

  File "/usr/local/python3/lib/python3.8/site-packages/urllib3/connectionpool.py", line 703, in urlopen
    httplib_response = self._make_request(
                       │    └ <function HTTPConnectionPool._make_request at 0x7f1bd7742550>
                       └ <urllib3.connectionpool.HTTPSConnectionPool object at 0x7f1b988f1820>
  File "/usr/local/python3/lib/python3.8/site-packages/urllib3/connectionpool.py", line 449, in _make_request
    six.raise_from(e, None)
    │   └ <function raise_from at 0x7f1bd77c29d0>
    └ <module 'urllib3.packages.six' from '/usr/local/python3/lib/python3.8/site-packages/urllib3/packages/six.py'>
  File "<string>", line 3, in raise_from
  File "/usr/local/python3/lib/python3.8/site-packages/urllib3/connectionpool.py", line 444, in _make_request
    httplib_response = conn.getresponse()
                       │    └ <function HTTPConnection.getresponse at 0x7f1bd85a2d30>
                       └ <urllib3.connection.HTTPSConnection object at 0x7f1b988e3250>
  File "/usr/local/python3/lib/python3.8/http/client.py", line 1322, in getresponse
    response.begin()
    │        └ <function HTTPResponse.begin at 0x7f1bd8c2f1f0>
    └ <http.client.HTTPResponse object at 0x7f1b988f1f40>
  File "/usr/local/python3/lib/python3.8/http/client.py", line 303, in begin
    version, status, reason = self._read_status()
                              │    └ <function HTTPResponse._read_status at 0x7f1bd8c2f160>
                              └ <http.client.HTTPResponse object at 0x7f1b988f1f40>
  File "/usr/local/python3/lib/python3.8/http/client.py", line 272, in _read_status
    raise RemoteDisconnected("Remote end closed connection without"
          └ <class 'http.client.RemoteDisconnected'>

http.client.RemoteDisconnected: Remote end closed connection without response


During handling of the above exception, another exception occurred:


Traceback (most recent call last):

  File "/usr/local/python3/lib/python3.8/site-packages/requests/adapters.py", line 440, in send
    resp = conn.urlopen(
           │    └ <function HTTPConnectionPool.urlopen at 0x7f1bd7742790>
           └ <urllib3.connectionpool.HTTPSConnectionPool object at 0x7f1b988f1820>
  File "/usr/local/python3/lib/python3.8/site-packages/urllib3/connectionpool.py", line 785, in urlopen
    retries = retries.increment(
              │       └ <function Retry.increment at 0x7f1bd7771670>
              └ Retry(total=0, connect=None, read=False, redirect=None, status=None)
  File "/usr/local/python3/lib/python3.8/site-packages/urllib3/util/retry.py", line 550, in increment
    raise six.reraise(type(error), error, _stacktrace)
          │   │            │       │      └ <traceback object at 0x7f1bb8a2c140>
          │   │            │       └ ProtocolError('Connection aborted.', RemoteDisconnected('Remote end closed connection without response'))
          │   │            └ ProtocolError('Connection aborted.', RemoteDisconnected('Remote end closed connection without response'))
          │   └ <function reraise at 0x7f1bd77c2940>
          └ <module 'urllib3.packages.six' from '/usr/local/python3/lib/python3.8/site-packages/urllib3/packages/six.py'>
  File "/usr/local/python3/lib/python3.8/site-packages/urllib3/packages/six.py", line 769, in reraise
    raise value.with_traceback(tb)
          │                    └ None
          └ None
  File "/usr/local/python3/lib/python3.8/site-packages/urllib3/connectionpool.py", line 703, in urlopen
    httplib_response = self._make_request(
                       │    └ <function HTTPConnectionPool._make_request at 0x7f1bd7742550>
                       └ <urllib3.connectionpool.HTTPSConnectionPool object at 0x7f1b988f1820>
  File "/usr/local/python3/lib/python3.8/site-packages/urllib3/connectionpool.py", line 449, in _make_request
    six.raise_from(e, None)
    │   └ <function raise_from at 0x7f1bd77c29d0>
    └ <module 'urllib3.packages.six' from '/usr/local/python3/lib/python3.8/site-packages/urllib3/packages/six.py'>
  File "<string>", line 3, in raise_from
  File "/usr/local/python3/lib/python3.8/site-packages/urllib3/connectionpool.py", line 444, in _make_request
    httplib_response = conn.getresponse()
                       │    └ <function HTTPConnection.getresponse at 0x7f1bd85a2d30>
                       └ <urllib3.connection.HTTPSConnection object at 0x7f1b988e3250>
  File "/usr/local/python3/lib/python3.8/http/client.py", line 1322, in getresponse
    response.begin()
    │        └ <function HTTPResponse.begin at 0x7f1bd8c2f1f0>
    └ <http.client.HTTPResponse object at 0x7f1b988f1f40>
  File "/usr/local/python3/lib/python3.8/http/client.py", line 303, in begin
    version, status, reason = self._read_status()
                              │    └ <function HTTPResponse._read_status at 0x7f1bd8c2f160>
                              └ <http.client.HTTPResponse object at 0x7f1b988f1f40>
  File "/usr/local/python3/lib/python3.8/http/client.py", line 272, in _read_status
    raise RemoteDisconnected("Remote end closed connection without"
          └ <class 'http.client.RemoteDisconnected'>

urllib3.exceptions.ProtocolError: ('Connection aborted.', RemoteDisconnected('Remote end closed connection without response'))


During handling of the above exception, another exception occurred:


Traceback (most recent call last):

  File "/usr/bin/nb", line 8, in <module>
    sys.exit(main())
    │   │    └ <ClickAliasedGroup main>
    │   └ <built-in function exit>
    └ <module 'sys' (built-in)>
  File "/usr/local/python3/lib/python3.8/site-packages/click/core.py", line 1128, in __call__
    return self.main(*args, **kwargs)
           │    │     │       └ {}
           │    │     └ ()
           │    └ <function BaseCommand.main at 0x7f1bdecad040>
           └ <ClickAliasedGroup main>
  File "/usr/local/python3/lib/python3.8/site-packages/click/core.py", line 1053, in main
    rv = self.invoke(ctx)
         │    │      └ <click.core.Context object at 0x7f1be6e21130>
         │    └ <function MultiCommand.invoke at 0x7f1bdecb10d0>
         └ <ClickAliasedGroup main>
  File "/usr/local/python3/lib/python3.8/site-packages/click/core.py", line 1659, in invoke
    return _process_result(sub_ctx.command.invoke(sub_ctx))
           │               │       │       │      └ <click.core.Context object at 0x7f1be6e26ca0>
           │               │       │       └ <function Command.invoke at 0x7f1bdecadaf0>
           │               │       └ <ClickAliasedCommand run>
           │               └ <click.core.Context object at 0x7f1be6e26ca0>
           └ <function MultiCommand.invoke.<locals>._process_result at 0x7f1bdf4f9a60>
  File "/usr/local/python3/lib/python3.8/site-packages/click/core.py", line 1395, in invoke
    return ctx.invoke(self.callback, **ctx.params)
           │   │      │    │           │   └ {'file': 'bot.py', 'app': 'app'}
           │   │      │    │           └ <click.core.Context object at 0x7f1be6e26ca0>
           │   │      │    └ <function run at 0x7f1bd5cf95e0>
           │   │      └ <ClickAliasedCommand run>
           │   └ <function Context.invoke at 0x7f1bdef2a8b0>
           └ <click.core.Context object at 0x7f1be6e26ca0>
  File "/usr/local/python3/lib/python3.8/site-packages/click/core.py", line 754, in invoke
    return __callback(*args, **kwargs)
                       │       └ {'file': 'bot.py', 'app': 'app'}
                       └ ()
  File "/usr/local/python3/lib/python3.8/site-packages/nb_cli/commands/main.py", line 30, in run
    run_bot(file, app)
    │       │     └ 'app'
    │       └ 'bot.py'
    └ <function run_bot at 0x7f1bd5ce93a0>
  File "/usr/local/python3/lib/python3.8/site-packages/nb_cli/handlers/deploy.py", line 24, in run_bot
    nonebot.run(app=f"{module_name}:{app}")
    │       └ <function run at 0x7f1bd7df2550>
    └ <module 'nonebot' from '/usr/local/python3/lib/python3.8/site-packages/nonebot/__init__.py'>
  File "/usr/local/python3/lib/python3.8/site-packages/nonebot/__init__.py", line 258, in run
    get_driver().run(*args, **kwargs)
    │                 │       └ {'app': 'bot:app'}
    │                 └ ()
    └ <function get_driver at 0x7f1bd7df20d0>
  File "/usr/local/python3/lib/python3.8/site-packages/nonebot/drivers/fastapi.py", line 168, in run
    uvicorn.run(
    │       └ <function run at 0x7f1bd5af5280>
    └ <module 'uvicorn' from '/usr/local/python3/lib/python3.8/site-packages/uvicorn/__init__.py'>
  File "/usr/local/python3/lib/python3.8/site-packages/uvicorn/main.py", line 463, in run
    server.run()
    │      └ <function Server.run at 0x7f1bd5af5670>
    └ <uvicorn.server.Server object at 0x7f1bb89d3be0>
  File "/usr/local/python3/lib/python3.8/site-packages/uvicorn/server.py", line 60, in run
    return asyncio.run(self.serve(sockets=sockets))
           │       │   │    │             └ None
           │       │   │    └ <function Server.serve at 0x7f1bd5af5700>
           │       │   └ <uvicorn.server.Server object at 0x7f1bb89d3be0>
           │       └ <function run at 0x7f1bdb5400d0>
           └ <module 'asyncio' from '/usr/local/python3/lib/python3.8/asyncio/__init__.py'>
  File "/usr/local/python3/lib/python3.8/asyncio/runners.py", line 43, in run
    return loop.run_until_complete(main)
           │    │                  └ <coroutine object Server.serve at 0x7f1bb89e5940>
           │    └ <method 'run_until_complete' of 'uvloop.loop.Loop' objects>
           └ <uvloop.Loop running=True closed=False debug=False>
  File "/usr/local/python3/lib/python3.8/site-packages/nonebot/message.py", line 153, in _check_matcher
    await _run_matcher(Matcher, bot, event, state, stack, dependency_cache)
          │            │        │    │      │      │      └ {<function _event_to_me at 0x7f1bd7e14c10>: <Task finished name='Task-364731' coro=<_event_to_me() done, defined at /usr/loca...
          │            │        │    │      │      └ <contextlib.AsyncExitStack object at 0x7f1b988e3610>
          │            │        │    │      └ {'_prefix': {'command': ('poem',), 'raw_command': '/poem', 'command_arg': []}}
          │            │        │    └ GroupMessageEvent(time=1646291357, self_id=507346814, post_type='message', sub_type='normal', user_id=2560359315, message_typ...
          │            │        └ <nonebot.adapters.onebot.v11.bot.Bot object at 0x7f1bb3d9ae20>
          │            └ <Matcher from src.plugins.nonebot_plugin_russian, type=message, priority=5, temp=False>
          └ <function _run_matcher at 0x7f1bd5c13280>
> File "/usr/local/python3/lib/python3.8/site-packages/nonebot/message.py", line 202, in _run_matcher
    await matcher.run(bot, event, state, stack, dependency_cache)
          │       │   │    │      │      │      └ {<function _event_to_me at 0x7f1bd7e14c10>: <Task finished name='Task-364731' coro=<_event_to_me() done, defined at /usr/loca...
          │       │   │    │      │      └ <contextlib.AsyncExitStack object at 0x7f1b988e3610>
          │       │   │    │      └ {'_prefix': {'command': ('poem',), 'raw_command': '/poem', 'command_arg': []}}
          │       │   │    └ GroupMessageEvent(time=1646291357, self_id=507346814, post_type='message', sub_type='normal', user_id=2560359315, message_typ...
          │       │   └ <nonebot.adapters.onebot.v11.bot.Bot object at 0x7f1bb3d9ae20>
          │       └ <function Matcher.run at 0x7f1bd7e14790>
          └ <Matcher from src.plugins.nonebot_plugin_russian, type=message, priority=5, temp=False>
  File "/usr/local/python3/lib/python3.8/site-packages/nonebot/internal/matcher.py", line 668, in run
    await self.simple_run(bot, event, state, stack, dependency_cache)
          │    │          │    │      │      │      └ {<function _event_to_me at 0x7f1bd7e14c10>: <Task finished name='Task-364731' coro=<_event_to_me() done, defined at /usr/loca...
          │    │          │    │      │      └ <contextlib.AsyncExitStack object at 0x7f1b988e3610>
          │    │          │    │      └ {'_prefix': {'command': ('poem',), 'raw_command': '/poem', 'command_arg': []}}
          │    │          │    └ GroupMessageEvent(time=1646291357, self_id=507346814, post_type='message', sub_type='normal', user_id=2560359315, message_typ...
          │    │          └ <nonebot.adapters.onebot.v11.bot.Bot object at 0x7f1bb3d9ae20>
          │    └ <function Matcher.simple_run at 0x7f1bd7e14700>
          └ <Matcher from src.plugins.nonebot_plugin_russian, type=message, priority=5, temp=False>
  File "/usr/local/python3/lib/python3.8/site-packages/nonebot/internal/matcher.py", line 635, in simple_run
    await handler(
          └ <Dependent call=<function _ at 0x7f1bc9da5670>, params=[ModelField(name='bot', type=Bot, required=True), ModelField(name='eve...
  File "/usr/local/python3/lib/python3.8/site-packages/nonebot/dependencies/__init__.py", line 92, in __call__
    return await self.call(**values)
                 │    │      └ {'bot': <nonebot.adapters.onebot.v11.bot.Bot object at 0x7f1bb3d9ae20>, 'event': GroupMessageEvent(time=1646291357, self_id=5...
                 │    └ <function _ at 0x7f1bc9da5670>
                 └ <Dependent call=<function _ at 0x7f1bc9da5670>, params=[ModelField(name='bot', type=Bot, required=True), ModelField(name='eve...

  File "./src/plugins/nonebot_plugin_russian/__init__.py", line 394, in _
    question = getQuestion(event.user_id)
               │           │     └ 2560359315
               │           └ GroupMessageEvent(time=1646291357, self_id=507346814, post_type='message', sub_type='normal', user_id=2560359315, message_typ...
               └ <function getQuestion at 0x7f1bc9df0430>

  File "./src/plugins/nonebot_plugin_russian/poem.py", line 17, in getQuestion
    resp = re.get(url.format("下一题", id))
           │  │   │   │             └ 2560359315
           │  │   │   └ <method 'format' of 'str' objects>
           │  │   └ 'https://api.iyk0.com/tzgsc/?msg={0}&id={1}'
           │  └ <function get at 0x7f1bd7283e50>
           └ <module 'requests' from '/usr/local/python3/lib/python3.8/site-packages/requests/__init__.py'>

  File "/usr/local/python3/lib/python3.8/site-packages/requests/api.py", line 75, in get
    return request('get', url, params=params, **kwargs)
           │              │           │         └ {}
           │              │           └ None
           │              └ 'https://api.iyk0.com/tzgsc/?msg=下一题&id=2560359315'
           └ <function request at 0x7f1bd726edc0>
  File "/usr/local/python3/lib/python3.8/site-packages/requests/api.py", line 61, in request
    return session.request(method=method, url=url, **kwargs)
           │       │              │           │      └ {'params': None}
           │       │              │           └ 'https://api.iyk0.com/tzgsc/?msg=下一题&id=2560359315'
           │       │              └ 'get'
           │       └ <function Session.request at 0x7f1bd72835e0>
           └ <requests.sessions.Session object at 0x7f1bb0869ca0>
  File "/usr/local/python3/lib/python3.8/site-packages/requests/sessions.py", line 529, in request
    resp = self.send(prep, **send_kwargs)
           │    │    │       └ {'timeout': None, 'allow_redirects': True, 'verify': True, 'proxies': OrderedDict(), 'stream': False, 'cert': None}
           │    │    └ <PreparedRequest [GET]>
           │    └ <function Session.send at 0x7f1bd7283a60>
           └ <requests.sessions.Session object at 0x7f1bb0869ca0>
  File "/usr/local/python3/lib/python3.8/site-packages/requests/sessions.py", line 645, in send
    r = adapter.send(request, **kwargs)
        │       │    │          └ {'timeout': None, 'verify': True, 'proxies': OrderedDict(), 'stream': False, 'cert': None}
        │       │    └ <PreparedRequest [GET]>
        │       └ <function HTTPAdapter.send at 0x7f1bd727aee0>
        └ <requests.adapters.HTTPAdapter object at 0x7f1b9b7c7f40>
  File "/usr/local/python3/lib/python3.8/site-packages/requests/adapters.py", line 501, in send
    raise ConnectionError(err, request=request)
          │                            └ <PreparedRequest [GET]>
          └ <class 'requests.exceptions.ConnectionError'>

requests.exceptions.ConnectionError: ('Connection aborted.', RemoteDisconnected('Remote end closed connection without response'))
[36mATRI[0m | 03-03 15:09:39 | ERROR nonebot >> Error when running RunPostProcessors
Traceback (most recent call last):

  File "/usr/bin/nb", line 8, in <module>
    sys.exit(main())
    │   │    └ <ClickAliasedGroup main>
    │   └ <built-in function exit>
    └ <module 'sys' (built-in)>
  File "/usr/local/python3/lib/python3.8/site-packages/click/core.py", line 1128, in __call__
    return self.main(*args, **kwargs)
           │    │     │       └ {}
           │    │     └ ()
           │    └ <function BaseCommand.main at 0x7f1bdecad040>
           └ <ClickAliasedGroup main>
  File "/usr/local/python3/lib/python3.8/site-packages/click/core.py", line 1053, in main
    rv = self.invoke(ctx)
         │    │      └ <click.core.Context object at 0x7f1be6e21130>
         │    └ <function MultiCommand.invoke at 0x7f1bdecb10d0>
         └ <ClickAliasedGroup main>
  File "/usr/local/python3/lib/python3.8/site-packages/click/core.py", line 1659, in invoke
    return _process_result(sub_ctx.command.invoke(sub_ctx))
           │               │       │       │      └ <click.core.Context object at 0x7f1be6e26ca0>
           │               │       │       └ <function Command.invoke at 0x7f1bdecadaf0>
           │               │       └ <ClickAliasedCommand run>
           │               └ <click.core.Context object at 0x7f1be6e26ca0>
           └ <function MultiCommand.invoke.<locals>._process_result at 0x7f1bdf4f9a60>
  File "/usr/local/python3/lib/python3.8/site-packages/click/core.py", line 1395, in invoke
    return ctx.invoke(self.callback, **ctx.params)
           │   │      │    │           │   └ {'file': 'bot.py', 'app': 'app'}
           │   │      │    │           └ <click.core.Context object at 0x7f1be6e26ca0>
           │   │      │    └ <function run at 0x7f1bd5cf95e0>
           │   │      └ <ClickAliasedCommand run>
           │   └ <function Context.invoke at 0x7f1bdef2a8b0>
           └ <click.core.Context object at 0x7f1be6e26ca0>
  File "/usr/local/python3/lib/python3.8/site-packages/click/core.py", line 754, in invoke
    return __callback(*args, **kwargs)
                       │       └ {'file': 'bot.py', 'app': 'app'}
                       └ ()
  File "/usr/local/python3/lib/python3.8/site-packages/nb_cli/commands/main.py", line 30, in run
    run_bot(file, app)
    │       │     └ 'app'
    │       └ 'bot.py'
    └ <function run_bot at 0x7f1bd5ce93a0>
  File "/usr/local/python3/lib/python3.8/site-packages/nb_cli/handlers/deploy.py", line 24, in run_bot
    nonebot.run(app=f"{module_name}:{app}")
    │       └ <function run at 0x7f1bd7df2550>
    └ <module 'nonebot' from '/usr/local/python3/lib/python3.8/site-packages/nonebot/__init__.py'>
  File "/usr/local/python3/lib/python3.8/site-packages/nonebot/__init__.py", line 258, in run
    get_driver().run(*args, **kwargs)
    │                 │       └ {'app': 'bot:app'}
    │                 └ ()
    └ <function get_driver at 0x7f1bd7df20d0>
  File "/usr/local/python3/lib/python3.8/site-packages/nonebot/drivers/fastapi.py", line 168, in run
    uvicorn.run(
    │       └ <function run at 0x7f1bd5af5280>
    └ <module 'uvicorn' from '/usr/local/python3/lib/python3.8/site-packages/uvicorn/__init__.py'>
  File "/usr/local/python3/lib/python3.8/site-packages/uvicorn/main.py", line 463, in run
    server.run()
    │      └ <function Server.run at 0x7f1bd5af5670>
    └ <uvicorn.server.Server object at 0x7f1bb89d3be0>
  File "/usr/local/python3/lib/python3.8/site-packages/uvicorn/server.py", line 60, in run
    return asyncio.run(self.serve(sockets=sockets))
           │       │   │    │             └ None
           │       │   │    └ <function Server.serve at 0x7f1bd5af5700>
           │       │   └ <uvicorn.server.Server object at 0x7f1bb89d3be0>
           │       └ <function run at 0x7f1bdb5400d0>
           └ <module 'asyncio' from '/usr/local/python3/lib/python3.8/asyncio/__init__.py'>
  File "/usr/local/python3/lib/python3.8/asyncio/runners.py", line 43, in run
    return loop.run_until_complete(main)
           │    │                  └ <coroutine object Server.serve at 0x7f1bb89e5940>
           │    └ <method 'run_until_complete' of 'uvloop.loop.Loop' objects>
           └ <uvloop.Loop running=True closed=False debug=False>
> File "/usr/local/python3/lib/python3.8/site-packages/nonebot/message.py", line 227, in _run_matcher
    await asyncio.gather(*coros)
          │       │       └ [<coroutine object _run_coro_with_catch at 0x7f1bb086f9c0>]
          │       └ <function gather at 0x7f1bd9364c10>
          └ <module 'asyncio' from '/usr/local/python3/lib/python3.8/asyncio/__init__.py'>
  File "/usr/local/python3/lib/python3.8/site-packages/nonebot/message.py", line 115, in _run_coro_with_catch
    return await coro
                 └ <coroutine object Dependent.__call__ at 0x7f1b9884a240>
  File "/usr/local/python3/lib/python3.8/site-packages/nonebot/dependencies/__init__.py", line 92, in __call__
    return await self.call(**values)
                 │    │      └ {'exception': ConnectionError(ProtocolError('Connection aborted.', RemoteDisconnected('Remote end closed connection without r...
                 │    └ <function _track_error at 0x7f1bc9bd3d30>
                 └ <Dependent call=<function _track_error at 0x7f1bc9bd3d30>, params=[ModelField(name='exception', type=Optional[Exception], req...
  File "/usr/local/python3/lib/python3.8/site-packages/ATRI/exceptions.py", line 115, in _track_error
    await bot.send_private_msg(user_id=superusers, message=msg)
          │                            │                   └ '呜——出错了...追踪: 1vXFy2hV'
          │                            └ '1234567890'
          └ <nonebot.adapters.onebot.v11.bot.Bot object at 0x7f1bb3d9ae20>
  File "/usr/local/python3/lib/python3.8/site-packages/nonebot/adapters/onebot/v11/bot.py", line 208, in call_api
    return await super().call_api(api, **data)
                                  │      └ {'user_id': '1234567890', 'message': '呜——出错了...追踪: 1vXFy2hV'}
                                  └ 'send_private_msg'
  File "/usr/local/python3/lib/python3.8/site-packages/nonebot/internal/adapter/bot.py", line 117, in call_api
    raise exception
          └ <ActionFailed data=None, echo={'seq': 59}, msg=SEND_MSG_API_ERROR, retcode=100, status=failed, wording=请参考 go-cqhttp 端输出>
  File "/usr/local/python3/lib/python3.8/site-packages/nonebot/internal/adapter/bot.py", line 94, in call_api
    result = await self.adapter._call_api(self, api, **data)
                   │    │       │         │     │      └ {'user_id': '1234567890', 'message': '呜——出错了...追踪: 1vXFy2hV'}
                   │    │       │         │     └ 'send_private_msg'
                   │    │       │         └ <nonebot.adapters.onebot.v11.bot.Bot object at 0x7f1bb3d9ae20>
                   │    │       └ <function Adapter._call_api at 0x7f1bd5c13b80>
                   │    └ <nonebot.adapters.onebot.v11.adapter.Adapter object at 0x7f1bd5cffa90>
                   └ <nonebot.adapters.onebot.v11.bot.Bot object at 0x7f1bb3d9ae20>
  File "/usr/local/python3/lib/python3.8/site-packages/nonebot/adapters/onebot/v11/adapter.py", line 107, in _call_api
    return _handle_api_result(
           └ <function _handle_api_result at 0x7f1bd5ca1310>
  File "/usr/local/python3/lib/python3.8/site-packages/nonebot/adapters/onebot/v11/utils.py", line 81, in _handle_api_result
    raise ActionFailed(**result)
          │              └ {'data': None, 'echo': {'seq': 59}, 'msg': 'SEND_MSG_API_ERROR', 'retcode': 100, 'status': 'failed', 'wording': '请参考 go-cqhtt...
          └ <class 'nonebot.adapters.onebot.v11.exception.ActionFailed'>

nonebot.adapters.onebot.v11.exception.ActionFailed: <ActionFailed data=None, echo={'seq': 59}, msg=SEND_MSG_API_ERROR, retcode=100, status=failed, wording=请参考 go-cqhttp 端输出>
[36mATRI[0m | 03-03 15:14:33 | ERROR nonebot >> Running matcher <Matcher from src.plugins.nonebot_plugin_russian, type=message, priority=5, temp=False> failed.
Traceback (most recent call last):

  File "/usr/bin/nb", line 8, in <module>
    sys.exit(main())
    │   │    └ <ClickAliasedGroup main>
    │   └ <built-in function exit>
    └ <module 'sys' (built-in)>
  File "/usr/local/python3/lib/python3.8/site-packages/click/core.py", line 1128, in __call__
    return self.main(*args, **kwargs)
           │    │     │       └ {}
           │    │     └ ()
           │    └ <function BaseCommand.main at 0x7f1bdecad040>
           └ <ClickAliasedGroup main>
  File "/usr/local/python3/lib/python3.8/site-packages/click/core.py", line 1053, in main
    rv = self.invoke(ctx)
         │    │      └ <click.core.Context object at 0x7f1be6e21130>
         │    └ <function MultiCommand.invoke at 0x7f1bdecb10d0>
         └ <ClickAliasedGroup main>
  File "/usr/local/python3/lib/python3.8/site-packages/click/core.py", line 1659, in invoke
    return _process_result(sub_ctx.command.invoke(sub_ctx))
           │               │       │       │      └ <click.core.Context object at 0x7f1be6e26ca0>
           │               │       │       └ <function Command.invoke at 0x7f1bdecadaf0>
           │               │       └ <ClickAliasedCommand run>
           │               └ <click.core.Context object at 0x7f1be6e26ca0>
           └ <function MultiCommand.invoke.<locals>._process_result at 0x7f1bdf4f9a60>
  File "/usr/local/python3/lib/python3.8/site-packages/click/core.py", line 1395, in invoke
    return ctx.invoke(self.callback, **ctx.params)
           │   │      │    │           │   └ {'file': 'bot.py', 'app': 'app'}
           │   │      │    │           └ <click.core.Context object at 0x7f1be6e26ca0>
           │   │      │    └ <function run at 0x7f1bd5cf95e0>
           │   │      └ <ClickAliasedCommand run>
           │   └ <function Context.invoke at 0x7f1bdef2a8b0>
           └ <click.core.Context object at 0x7f1be6e26ca0>
  File "/usr/local/python3/lib/python3.8/site-packages/click/core.py", line 754, in invoke
    return __callback(*args, **kwargs)
                       │       └ {'file': 'bot.py', 'app': 'app'}
                       └ ()
  File "/usr/local/python3/lib/python3.8/site-packages/nb_cli/commands/main.py", line 30, in run
    run_bot(file, app)
    │       │     └ 'app'
    │       └ 'bot.py'
    └ <function run_bot at 0x7f1bd5ce93a0>
  File "/usr/local/python3/lib/python3.8/site-packages/nb_cli/handlers/deploy.py", line 24, in run_bot
    nonebot.run(app=f"{module_name}:{app}")
    │       └ <function run at 0x7f1bd7df2550>
    └ <module 'nonebot' from '/usr/local/python3/lib/python3.8/site-packages/nonebot/__init__.py'>
  File "/usr/local/python3/lib/python3.8/site-packages/nonebot/__init__.py", line 258, in run
    get_driver().run(*args, **kwargs)
    │                 │       └ {'app': 'bot:app'}
    │                 └ ()
    └ <function get_driver at 0x7f1bd7df20d0>
  File "/usr/local/python3/lib/python3.8/site-packages/nonebot/drivers/fastapi.py", line 168, in run
    uvicorn.run(
    │       └ <function run at 0x7f1bd5af5280>
    └ <module 'uvicorn' from '/usr/local/python3/lib/python3.8/site-packages/uvicorn/__init__.py'>
  File "/usr/local/python3/lib/python3.8/site-packages/uvicorn/main.py", line 463, in run
    server.run()
    │      └ <function Server.run at 0x7f1bd5af5670>
    └ <uvicorn.server.Server object at 0x7f1bb89d3be0>
  File "/usr/local/python3/lib/python3.8/site-packages/uvicorn/server.py", line 60, in run
    return asyncio.run(self.serve(sockets=sockets))
           │       │   │    │             └ None
           │       │   │    └ <function Server.serve at 0x7f1bd5af5700>
           │       │   └ <uvicorn.server.Server object at 0x7f1bb89d3be0>
           │       └ <function run at 0x7f1bdb5400d0>
           └ <module 'asyncio' from '/usr/local/python3/lib/python3.8/asyncio/__init__.py'>
  File "/usr/local/python3/lib/python3.8/asyncio/runners.py", line 43, in run
    return loop.run_until_complete(main)
           │    │                  └ <coroutine object Server.serve at 0x7f1bb89e5940>
           │    └ <method 'run_until_complete' of 'uvloop.loop.Loop' objects>
           └ <uvloop.Loop running=True closed=False debug=False>
  File "/usr/local/python3/lib/python3.8/site-packages/nonebot/message.py", line 153, in _check_matcher
    await _run_matcher(Matcher, bot, event, state, stack, dependency_cache)
          │            │        │    │      │      │      └ {<function _event_to_me at 0x7f1bd7e14c10>: <Task finished name='Task-383726' coro=<_event_to_me() done, defined at /usr/loca...
          │            │        │    │      │      └ <contextlib.AsyncExitStack object at 0x7f1b987ede80>
          │            │        │    │      └ {'_prefix': {'command': ('拒绝对决',), 'raw_command': '/拒绝对决', 'command_arg': []}}
          │            │        │    └ GroupMessageEvent(time=1646291673, self_id=507346814, post_type='message', sub_type='normal', user_id=2560359315, message_typ...
          │            │        └ <nonebot.adapters.onebot.v11.bot.Bot object at 0x7f1bb3d9ae20>
          │            └ <Matcher from src.plugins.nonebot_plugin_russian, type=message, priority=5, temp=False>
          └ <function _run_matcher at 0x7f1bd5c13280>
> File "/usr/local/python3/lib/python3.8/site-packages/nonebot/message.py", line 202, in _run_matcher
    await matcher.run(bot, event, state, stack, dependency_cache)
          │       │   │    │      │      │      └ {<function _event_to_me at 0x7f1bd7e14c10>: <Task finished name='Task-383726' coro=<_event_to_me() done, defined at /usr/loca...
          │       │   │    │      │      └ <contextlib.AsyncExitStack object at 0x7f1b987ede80>
          │       │   │    │      └ {'_prefix': {'command': ('拒绝对决',), 'raw_command': '/拒绝对决', 'command_arg': []}}
          │       │   │    └ GroupMessageEvent(time=1646291673, self_id=507346814, post_type='message', sub_type='normal', user_id=2560359315, message_typ...
          │       │   └ <nonebot.adapters.onebot.v11.bot.Bot object at 0x7f1bb3d9ae20>
          │       └ <function Matcher.run at 0x7f1bd7e14790>
          └ <Matcher from src.plugins.nonebot_plugin_russian, type=message, priority=5, temp=False>
  File "/usr/local/python3/lib/python3.8/site-packages/nonebot/internal/matcher.py", line 668, in run
    await self.simple_run(bot, event, state, stack, dependency_cache)
          │    │          │    │      │      │      └ {<function _event_to_me at 0x7f1bd7e14c10>: <Task finished name='Task-383726' coro=<_event_to_me() done, defined at /usr/loca...
          │    │          │    │      │      └ <contextlib.AsyncExitStack object at 0x7f1b987ede80>
          │    │          │    │      └ {'_prefix': {'command': ('拒绝对决',), 'raw_command': '/拒绝对决', 'command_arg': []}}
          │    │          │    └ GroupMessageEvent(time=1646291673, self_id=507346814, post_type='message', sub_type='normal', user_id=2560359315, message_typ...
          │    │          └ <nonebot.adapters.onebot.v11.bot.Bot object at 0x7f1bb3d9ae20>
          │    └ <function Matcher.simple_run at 0x7f1bd7e14700>
          └ <Matcher from src.plugins.nonebot_plugin_russian, type=message, priority=5, temp=False>
  File "/usr/local/python3/lib/python3.8/site-packages/nonebot/internal/matcher.py", line 635, in simple_run
    await handler(
          └ <Dependent call=<function _ at 0x7f1bc9df0d30>, params=[ModelField(name='bot', type=Bot, required=True), ModelField(name='eve...
  File "/usr/local/python3/lib/python3.8/site-packages/nonebot/dependencies/__init__.py", line 92, in __call__
    return await self.call(**values)
                 │    │      └ {'bot': <nonebot.adapters.onebot.v11.bot.Bot object at 0x7f1bb3d9ae20>, 'event': GroupMessageEvent(time=1646291673, self_id=5...
                 │    └ <function _ at 0x7f1bc9df0d30>
                 └ <Dependent call=<function _ at 0x7f1bc9df0d30>, params=[ModelField(name='bot', type=Bot, required=True), ModelField(name='eve...

  File "./src/plugins/nonebot_plugin_russian/__init__.py", line 102, in _
    msg = await russian_manager.refuse(bot, event)
                │               │      │    └ GroupMessageEvent(time=1646291673, self_id=507346814, post_type='message', sub_type='normal', user_id=2560359315, message_typ...
                │               │      └ <nonebot.adapters.onebot.v11.bot.Bot object at 0x7f1bb3d9ae20>
                │               └ <function RussianManager.refuse at 0x7f1bc9e34ee0>
                └ <src.plugins.nonebot_plugin_russian.data_source.RussianManager object at 0x7f1bc9de3310>

  File "./src/plugins/nonebot_plugin_russian/data_source.py", line 193, in refuse
    f"{MessageSegment.at(self._current_player[event.group_id][1])}\n"

KeyError: 1
[36mATRI[0m | 03-03 15:14:34 | ERROR nonebot >> Error when running RunPostProcessors
Traceback (most recent call last):

  File "/usr/bin/nb", line 8, in <module>
    sys.exit(main())
    │   │    └ <ClickAliasedGroup main>
    │   └ <built-in function exit>
    └ <module 'sys' (built-in)>
  File "/usr/local/python3/lib/python3.8/site-packages/click/core.py", line 1128, in __call__
    return self.main(*args, **kwargs)
           │    │     │       └ {}
           │    │     └ ()
           │    └ <function BaseCommand.main at 0x7f1bdecad040>
           └ <ClickAliasedGroup main>
  File "/usr/local/python3/lib/python3.8/site-packages/click/core.py", line 1053, in main
    rv = self.invoke(ctx)
         │    │      └ <click.core.Context object at 0x7f1be6e21130>
         │    └ <function MultiCommand.invoke at 0x7f1bdecb10d0>
         └ <ClickAliasedGroup main>
  File "/usr/local/python3/lib/python3.8/site-packages/click/core.py", line 1659, in invoke
    return _process_result(sub_ctx.command.invoke(sub_ctx))
           │               │       │       │      └ <click.core.Context object at 0x7f1be6e26ca0>
           │               │       │       └ <function Command.invoke at 0x7f1bdecadaf0>
           │               │       └ <ClickAliasedCommand run>
           │               └ <click.core.Context object at 0x7f1be6e26ca0>
           └ <function MultiCommand.invoke.<locals>._process_result at 0x7f1bdf4f9a60>
  File "/usr/local/python3/lib/python3.8/site-packages/click/core.py", line 1395, in invoke
    return ctx.invoke(self.callback, **ctx.params)
           │   │      │    │           │   └ {'file': 'bot.py', 'app': 'app'}
           │   │      │    │           └ <click.core.Context object at 0x7f1be6e26ca0>
           │   │      │    └ <function run at 0x7f1bd5cf95e0>
           │   │      └ <ClickAliasedCommand run>
           │   └ <function Context.invoke at 0x7f1bdef2a8b0>
           └ <click.core.Context object at 0x7f1be6e26ca0>
  File "/usr/local/python3/lib/python3.8/site-packages/click/core.py", line 754, in invoke
    return __callback(*args, **kwargs)
                       │       └ {'file': 'bot.py', 'app': 'app'}
                       └ ()
  File "/usr/local/python3/lib/python3.8/site-packages/nb_cli/commands/main.py", line 30, in run
    run_bot(file, app)
    │       │     └ 'app'
    │       └ 'bot.py'
    └ <function run_bot at 0x7f1bd5ce93a0>
  File "/usr/local/python3/lib/python3.8/site-packages/nb_cli/handlers/deploy.py", line 24, in run_bot
    nonebot.run(app=f"{module_name}:{app}")
    │       └ <function run at 0x7f1bd7df2550>
    └ <module 'nonebot' from '/usr/local/python3/lib/python3.8/site-packages/nonebot/__init__.py'>
  File "/usr/local/python3/lib/python3.8/site-packages/nonebot/__init__.py", line 258, in run
    get_driver().run(*args, **kwargs)
    │                 │       └ {'app': 'bot:app'}
    │                 └ ()
    └ <function get_driver at 0x7f1bd7df20d0>
  File "/usr/local/python3/lib/python3.8/site-packages/nonebot/drivers/fastapi.py", line 168, in run
    uvicorn.run(
    │       └ <function run at 0x7f1bd5af5280>
    └ <module 'uvicorn' from '/usr/local/python3/lib/python3.8/site-packages/uvicorn/__init__.py'>
  File "/usr/local/python3/lib/python3.8/site-packages/uvicorn/main.py", line 463, in run
    server.run()
    │      └ <function Server.run at 0x7f1bd5af5670>
    └ <uvicorn.server.Server object at 0x7f1bb89d3be0>
  File "/usr/local/python3/lib/python3.8/site-packages/uvicorn/server.py", line 60, in run
    return asyncio.run(self.serve(sockets=sockets))
           │       │   │    │             └ None
           │       │   │    └ <function Server.serve at 0x7f1bd5af5700>
           │       │   └ <uvicorn.server.Server object at 0x7f1bb89d3be0>
           │       └ <function run at 0x7f1bdb5400d0>
           └ <module 'asyncio' from '/usr/local/python3/lib/python3.8/asyncio/__init__.py'>
  File "/usr/local/python3/lib/python3.8/asyncio/runners.py", line 43, in run
    return loop.run_until_complete(main)
           │    │                  └ <coroutine object Server.serve at 0x7f1bb89e5940>
           │    └ <method 'run_until_complete' of 'uvloop.loop.Loop' objects>
           └ <uvloop.Loop running=True closed=False debug=False>
> File "/usr/local/python3/lib/python3.8/site-packages/nonebot/message.py", line 227, in _run_matcher
    await asyncio.gather(*coros)
          │       │       └ [<coroutine object _run_coro_with_catch at 0x7f1bb3da69c0>]
          │       └ <function gather at 0x7f1bd9364c10>
          └ <module 'asyncio' from '/usr/local/python3/lib/python3.8/asyncio/__init__.py'>
  File "/usr/local/python3/lib/python3.8/site-packages/nonebot/message.py", line 115, in _run_coro_with_catch
    return await coro
                 └ <coroutine object Dependent.__call__ at 0x7f1b98871e40>
  File "/usr/local/python3/lib/python3.8/site-packages/nonebot/dependencies/__init__.py", line 92, in __call__
    return await self.call(**values)
                 │    │      └ {'exception': KeyError(1), 'bot': <nonebot.adapters.onebot.v11.bot.Bot object at 0x7f1bb3d9ae20>}
                 │    └ <function _track_error at 0x7f1bc9bd3d30>
                 └ <Dependent call=<function _track_error at 0x7f1bc9bd3d30>, params=[ModelField(name='exception', type=Optional[Exception], req...
  File "/usr/local/python3/lib/python3.8/site-packages/ATRI/exceptions.py", line 115, in _track_error
    await bot.send_private_msg(user_id=superusers, message=msg)
          │                            │                   └ '呜——出错了...追踪: 0MehFqyG'
          │                            └ '1234567890'
          └ <nonebot.adapters.onebot.v11.bot.Bot object at 0x7f1bb3d9ae20>
  File "/usr/local/python3/lib/python3.8/site-packages/nonebot/adapters/onebot/v11/bot.py", line 208, in call_api
    return await super().call_api(api, **data)
                                  │      └ {'user_id': '1234567890', 'message': '呜——出错了...追踪: 0MehFqyG'}
                                  └ 'send_private_msg'
  File "/usr/local/python3/lib/python3.8/site-packages/nonebot/internal/adapter/bot.py", line 117, in call_api
    raise exception
          └ <ActionFailed data=None, echo={'seq': 124}, msg=SEND_MSG_API_ERROR, retcode=100, status=failed, wording=请参考 go-cqhttp 端输出>
  File "/usr/local/python3/lib/python3.8/site-packages/nonebot/internal/adapter/bot.py", line 94, in call_api
    result = await self.adapter._call_api(self, api, **data)
                   │    │       │         │     │      └ {'user_id': '1234567890', 'message': '呜——出错了...追踪: 0MehFqyG'}
                   │    │       │         │     └ 'send_private_msg'
                   │    │       │         └ <nonebot.adapters.onebot.v11.bot.Bot object at 0x7f1bb3d9ae20>
                   │    │       └ <function Adapter._call_api at 0x7f1bd5c13b80>
                   │    └ <nonebot.adapters.onebot.v11.adapter.Adapter object at 0x7f1bd5cffa90>
                   └ <nonebot.adapters.onebot.v11.bot.Bot object at 0x7f1bb3d9ae20>
  File "/usr/local/python3/lib/python3.8/site-packages/nonebot/adapters/onebot/v11/adapter.py", line 107, in _call_api
    return _handle_api_result(
           └ <function _handle_api_result at 0x7f1bd5ca1310>
  File "/usr/local/python3/lib/python3.8/site-packages/nonebot/adapters/onebot/v11/utils.py", line 81, in _handle_api_result
    raise ActionFailed(**result)
          │              └ {'data': None, 'echo': {'seq': 124}, 'msg': 'SEND_MSG_API_ERROR', 'retcode': 100, 'status': 'failed', 'wording': '请参考 go-cqht...
          └ <class 'nonebot.adapters.onebot.v11.exception.ActionFailed'>

nonebot.adapters.onebot.v11.exception.ActionFailed: <ActionFailed data=None, echo={'seq': 124}, msg=SEND_MSG_API_ERROR, retcode=100, status=failed, wording=请参考 go-cqhttp 端输出>
[36mATRI[0m | 03-03 15:16:57 | ERROR nonebot >> Running matcher <Matcher from src.plugins.nonebot_plugin_russian, type=message, priority=5, temp=False> failed.
Traceback (most recent call last):

  File "/usr/bin/nb", line 8, in <module>
    sys.exit(main())
    │   │    └ <ClickAliasedGroup main>
    │   └ <built-in function exit>
    └ <module 'sys' (built-in)>
  File "/usr/local/python3/lib/python3.8/site-packages/click/core.py", line 1128, in __call__
    return self.main(*args, **kwargs)
           │    │     │       └ {}
           │    │     └ ()
           │    └ <function BaseCommand.main at 0x7f1bdecad040>
           └ <ClickAliasedGroup main>
  File "/usr/local/python3/lib/python3.8/site-packages/click/core.py", line 1053, in main
    rv = self.invoke(ctx)
         │    │      └ <click.core.Context object at 0x7f1be6e21130>
         │    └ <function MultiCommand.invoke at 0x7f1bdecb10d0>
         └ <ClickAliasedGroup main>
  File "/usr/local/python3/lib/python3.8/site-packages/click/core.py", line 1659, in invoke
    return _process_result(sub_ctx.command.invoke(sub_ctx))
           │               │       │       │      └ <click.core.Context object at 0x7f1be6e26ca0>
           │               │       │       └ <function Command.invoke at 0x7f1bdecadaf0>
           │               │       └ <ClickAliasedCommand run>
           │               └ <click.core.Context object at 0x7f1be6e26ca0>
           └ <function MultiCommand.invoke.<locals>._process_result at 0x7f1bdf4f9a60>
  File "/usr/local/python3/lib/python3.8/site-packages/click/core.py", line 1395, in invoke
    return ctx.invoke(self.callback, **ctx.params)
           │   │      │    │           │   └ {'file': 'bot.py', 'app': 'app'}
           │   │      │    │           └ <click.core.Context object at 0x7f1be6e26ca0>
           │   │      │    └ <function run at 0x7f1bd5cf95e0>
           │   │      └ <ClickAliasedCommand run>
           │   └ <function Context.invoke at 0x7f1bdef2a8b0>
           └ <click.core.Context object at 0x7f1be6e26ca0>
  File "/usr/local/python3/lib/python3.8/site-packages/click/core.py", line 754, in invoke
    return __callback(*args, **kwargs)
                       │       └ {'file': 'bot.py', 'app': 'app'}
                       └ ()
  File "/usr/local/python3/lib/python3.8/site-packages/nb_cli/commands/main.py", line 30, in run
    run_bot(file, app)
    │       │     └ 'app'
    │       └ 'bot.py'
    └ <function run_bot at 0x7f1bd5ce93a0>
  File "/usr/local/python3/lib/python3.8/site-packages/nb_cli/handlers/deploy.py", line 24, in run_bot
    nonebot.run(app=f"{module_name}:{app}")
    │       └ <function run at 0x7f1bd7df2550>
    └ <module 'nonebot' from '/usr/local/python3/lib/python3.8/site-packages/nonebot/__init__.py'>
  File "/usr/local/python3/lib/python3.8/site-packages/nonebot/__init__.py", line 258, in run
    get_driver().run(*args, **kwargs)
    │                 │       └ {'app': 'bot:app'}
    │                 └ ()
    └ <function get_driver at 0x7f1bd7df20d0>
  File "/usr/local/python3/lib/python3.8/site-packages/nonebot/drivers/fastapi.py", line 168, in run
    uvicorn.run(
    │       └ <function run at 0x7f1bd5af5280>
    └ <module 'uvicorn' from '/usr/local/python3/lib/python3.8/site-packages/uvicorn/__init__.py'>
  File "/usr/local/python3/lib/python3.8/site-packages/uvicorn/main.py", line 463, in run
    server.run()
    │      └ <function Server.run at 0x7f1bd5af5670>
    └ <uvicorn.server.Server object at 0x7f1bb89d3be0>
  File "/usr/local/python3/lib/python3.8/site-packages/uvicorn/server.py", line 60, in run
    return asyncio.run(self.serve(sockets=sockets))
           │       │   │    │             └ None
           │       │   │    └ <function Server.serve at 0x7f1bd5af5700>
           │       │   └ <uvicorn.server.Server object at 0x7f1bb89d3be0>
           │       └ <function run at 0x7f1bdb5400d0>
           └ <module 'asyncio' from '/usr/local/python3/lib/python3.8/asyncio/__init__.py'>
  File "/usr/local/python3/lib/python3.8/asyncio/runners.py", line 43, in run
    return loop.run_until_complete(main)
           │    │                  └ <coroutine object Server.serve at 0x7f1bb89e5940>
           │    └ <method 'run_until_complete' of 'uvloop.loop.Loop' objects>
           └ <uvloop.Loop running=True closed=False debug=False>
  File "/usr/local/python3/lib/python3.8/site-packages/nonebot/message.py", line 153, in _check_matcher
    await _run_matcher(Matcher, bot, event, state, stack, dependency_cache)
          │            │        │    │      │      │      └ {<function _event_to_me at 0x7f1bd7e14c10>: <Task finished name='Task-394444' coro=<_event_to_me() done, defined at /usr/loca...
          │            │        │    │      │      └ <contextlib.AsyncExitStack object at 0x7f1b987fc910>
          │            │        │    │      └ {'_prefix': {'command': ('咔',), 'raw_command': '/咔', 'command_arg': []}}
          │            │        │    └ GroupMessageEvent(time=1646291811, self_id=507346814, post_type='message', sub_type='normal', user_id=2560359315, message_typ...
          │            │        └ <nonebot.adapters.onebot.v11.bot.Bot object at 0x7f1bb3d9ae20>
          │            └ <Matcher from src.plugins.nonebot_plugin_russian, type=message, priority=5, temp=False>
          └ <function _run_matcher at 0x7f1bd5c13280>
> File "/usr/local/python3/lib/python3.8/site-packages/nonebot/message.py", line 202, in _run_matcher
    await matcher.run(bot, event, state, stack, dependency_cache)
          │       │   │    │      │      │      └ {<function _event_to_me at 0x7f1bd7e14c10>: <Task finished name='Task-394444' coro=<_event_to_me() done, defined at /usr/loca...
          │       │   │    │      │      └ <contextlib.AsyncExitStack object at 0x7f1b987fc910>
          │       │   │    │      └ {'_prefix': {'command': ('咔',), 'raw_command': '/咔', 'command_arg': []}}
          │       │   │    └ GroupMessageEvent(time=1646291811, self_id=507346814, post_type='message', sub_type='normal', user_id=2560359315, message_typ...
          │       │   └ <nonebot.adapters.onebot.v11.bot.Bot object at 0x7f1bb3d9ae20>
          │       └ <function Matcher.run at 0x7f1bd7e14790>
          └ <Matcher from src.plugins.nonebot_plugin_russian, type=message, priority=5, temp=False>
  File "/usr/local/python3/lib/python3.8/site-packages/nonebot/internal/matcher.py", line 668, in run
    await self.simple_run(bot, event, state, stack, dependency_cache)
          │    │          │    │      │      │      └ {<function _event_to_me at 0x7f1bd7e14c10>: <Task finished name='Task-394444' coro=<_event_to_me() done, defined at /usr/loca...
          │    │          │    │      │      └ <contextlib.AsyncExitStack object at 0x7f1b987fc910>
          │    │          │    │      └ {'_prefix': {'command': ('咔',), 'raw_command': '/咔', 'command_arg': []}}
          │    │          │    └ GroupMessageEvent(time=1646291811, self_id=507346814, post_type='message', sub_type='normal', user_id=2560359315, message_typ...
          │    │          └ <nonebot.adapters.onebot.v11.bot.Bot object at 0x7f1bb3d9ae20>
          │    └ <function Matcher.simple_run at 0x7f1bd7e14700>
          └ <Matcher from src.plugins.nonebot_plugin_russian, type=message, priority=5, temp=False>
  File "/usr/local/python3/lib/python3.8/site-packages/nonebot/internal/matcher.py", line 635, in simple_run
    await handler(
          └ <Dependent call=<function _ at 0x7f1bc9da50d0>, params=[ModelField(name='bot', type=Bot, required=True), ModelField(name='eve...
  File "/usr/local/python3/lib/python3.8/site-packages/nonebot/dependencies/__init__.py", line 92, in __call__
    return await self.call(**values)
                 │    │      └ {'bot': <nonebot.adapters.onebot.v11.bot.Bot object at 0x7f1bb3d9ae20>, 'event': GroupMessageEvent(time=1646291811, self_id=5...
                 │    └ <function _ at 0x7f1bc9da50d0>
                 └ <Dependent call=<function _ at 0x7f1bc9da50d0>, params=[ModelField(name='bot', type=Bot, required=True), ModelField(name='eve...

  File "./src/plugins/nonebot_plugin_russian/__init__.py", line 214, in _
    await russian_manager.shot(bot, event, count)
          │               │    │    │      └ 1
          │               │    │    └ GroupMessageEvent(time=1646291811, self_id=507346814, post_type='message', sub_type='normal', user_id=2560359315, message_typ...
          │               │    └ <nonebot.adapters.onebot.v11.bot.Bot object at 0x7f1bb3d9ae20>
          │               └ <function RussianManager.shot at 0x7f1bc9de9160>
          └ <src.plugins.nonebot_plugin_russian.data_source.RussianManager object at 0x7f1bc9de3310>

  File "./src/plugins/nonebot_plugin_russian/data_source.py", line 341, in shot
    await bot.send(
          │   └ <function Bot.send at 0x7f1bd5c13790>
          └ <nonebot.adapters.onebot.v11.bot.Bot object at 0x7f1bb3d9ae20>

  File "/usr/local/python3/lib/python3.8/site-packages/nonebot/adapters/onebot/v11/bot.py", line 247, in send
    return await self.__class__.send_handler(self, event, message, **kwargs)
                 │    │                      │     │      │          └ {}
                 │    │                      │     │      └ [MessageSegment(type='text', data={'text': '虽然黑洞洞的枪口很恐怖，但好在没有子弹射出来，你活下来了\n下一枪中弹的概率：40.0%\n轮到 '}), MessageSegment(type='at', d...
                 │    │                      │     └ GroupMessageEvent(time=1646291811, self_id=507346814, post_type='message', sub_type='normal', user_id=2560359315, message_typ...
                 │    │                      └ <nonebot.adapters.onebot.v11.bot.Bot object at 0x7f1bb3d9ae20>
                 │    └ <attribute '__class__' of 'object' objects>
                 └ <nonebot.adapters.onebot.v11.bot.Bot object at 0x7f1bb3d9ae20>
  File "/usr/local/python3/lib/python3.8/site-packages/nonebot/adapters/onebot/v11/bot.py", line 175, in send
    return await bot.send_msg(**params)
                 │              └ {'user_id': 2560359315, 'group_id': 937760225, 'message_type': 'group', 'message': [MessageSegment(type='text', data={'text':...
                 └ <nonebot.adapters.onebot.v11.bot.Bot object at 0x7f1bb3d9ae20>
  File "/usr/local/python3/lib/python3.8/site-packages/nonebot/adapters/onebot/v11/bot.py", line 208, in call_api
    return await super().call_api(api, **data)
                                  │      └ {'user_id': 2560359315, 'group_id': 937760225, 'message_type': 'group', 'message': [MessageSegment(type='text', data={'text':...
                                  └ 'send_msg'
  File "/usr/local/python3/lib/python3.8/site-packages/nonebot/internal/adapter/bot.py", line 117, in call_api
    raise exception
          └ <ActionFailed data=None, echo={'seq': 145}, msg=SEND_MSG_API_ERROR, retcode=100, status=failed, wording=请参考 go-cqhttp 端输出>
  File "/usr/local/python3/lib/python3.8/site-packages/nonebot/internal/adapter/bot.py", line 94, in call_api
    result = await self.adapter._call_api(self, api, **data)
                   │    │       │         │     │      └ {'user_id': 2560359315, 'group_id': 937760225, 'message_type': 'group', 'message': [MessageSegment(type='text', data={'text':...
                   │    │       │         │     └ 'send_msg'
                   │    │       │         └ <nonebot.adapters.onebot.v11.bot.Bot object at 0x7f1bb3d9ae20>
                   │    │       └ <function Adapter._call_api at 0x7f1bd5c13b80>
                   │    └ <nonebot.adapters.onebot.v11.adapter.Adapter object at 0x7f1bd5cffa90>
                   └ <nonebot.adapters.onebot.v11.bot.Bot object at 0x7f1bb3d9ae20>
  File "/usr/local/python3/lib/python3.8/site-packages/nonebot/adapters/onebot/v11/adapter.py", line 107, in _call_api
    return _handle_api_result(
           └ <function _handle_api_result at 0x7f1bd5ca1310>
  File "/usr/local/python3/lib/python3.8/site-packages/nonebot/adapters/onebot/v11/utils.py", line 81, in _handle_api_result
    raise ActionFailed(**result)
          │              └ {'data': None, 'echo': {'seq': 145}, 'msg': 'SEND_MSG_API_ERROR', 'retcode': 100, 'status': 'failed', 'wording': '请参考 go-cqht...
          └ <class 'nonebot.adapters.onebot.v11.exception.ActionFailed'>

nonebot.adapters.onebot.v11.exception.ActionFailed: <ActionFailed data=None, echo={'seq': 145}, msg=SEND_MSG_API_ERROR, retcode=100, status=failed, wording=请参考 go-cqhttp 端输出>
[36mATRI[0m | 03-03 15:16:57 | ERROR nonebot >> Error when running RunPostProcessors
Traceback (most recent call last):

  File "/usr/bin/nb", line 8, in <module>
    sys.exit(main())
    │   │    └ <ClickAliasedGroup main>
    │   └ <built-in function exit>
    └ <module 'sys' (built-in)>
  File "/usr/local/python3/lib/python3.8/site-packages/click/core.py", line 1128, in __call__
    return self.main(*args, **kwargs)
           │    │     │       └ {}
           │    │     └ ()
           │    └ <function BaseCommand.main at 0x7f1bdecad040>
           └ <ClickAliasedGroup main>
  File "/usr/local/python3/lib/python3.8/site-packages/click/core.py", line 1053, in main
    rv = self.invoke(ctx)
         │    │      └ <click.core.Context object at 0x7f1be6e21130>
         │    └ <function MultiCommand.invoke at 0x7f1bdecb10d0>
         └ <ClickAliasedGroup main>
  File "/usr/local/python3/lib/python3.8/site-packages/click/core.py", line 1659, in invoke
    return _process_result(sub_ctx.command.invoke(sub_ctx))
           │               │       │       │      └ <click.core.Context object at 0x7f1be6e26ca0>
           │               │       │       └ <function Command.invoke at 0x7f1bdecadaf0>
           │               │       └ <ClickAliasedCommand run>
           │               └ <click.core.Context object at 0x7f1be6e26ca0>
           └ <function MultiCommand.invoke.<locals>._process_result at 0x7f1bdf4f9a60>
  File "/usr/local/python3/lib/python3.8/site-packages/click/core.py", line 1395, in invoke
    return ctx.invoke(self.callback, **ctx.params)
           │   │      │    │           │   └ {'file': 'bot.py', 'app': 'app'}
           │   │      │    │           └ <click.core.Context object at 0x7f1be6e26ca0>
           │   │      │    └ <function run at 0x7f1bd5cf95e0>
           │   │      └ <ClickAliasedCommand run>
           │   └ <function Context.invoke at 0x7f1bdef2a8b0>
           └ <click.core.Context object at 0x7f1be6e26ca0>
  File "/usr/local/python3/lib/python3.8/site-packages/click/core.py", line 754, in invoke
    return __callback(*args, **kwargs)
                       │       └ {'file': 'bot.py', 'app': 'app'}
                       └ ()
  File "/usr/local/python3/lib/python3.8/site-packages/nb_cli/commands/main.py", line 30, in run
    run_bot(file, app)
    │       │     └ 'app'
    │       └ 'bot.py'
    └ <function run_bot at 0x7f1bd5ce93a0>
  File "/usr/local/python3/lib/python3.8/site-packages/nb_cli/handlers/deploy.py", line 24, in run_bot
    nonebot.run(app=f"{module_name}:{app}")
    │       └ <function run at 0x7f1bd7df2550>
    └ <module 'nonebot' from '/usr/local/python3/lib/python3.8/site-packages/nonebot/__init__.py'>
  File "/usr/local/python3/lib/python3.8/site-packages/nonebot/__init__.py", line 258, in run
    get_driver().run(*args, **kwargs)
    │                 │       └ {'app': 'bot:app'}
    │                 └ ()
    └ <function get_driver at 0x7f1bd7df20d0>
  File "/usr/local/python3/lib/python3.8/site-packages/nonebot/drivers/fastapi.py", line 168, in run
    uvicorn.run(
    │       └ <function run at 0x7f1bd5af5280>
    └ <module 'uvicorn' from '/usr/local/python3/lib/python3.8/site-packages/uvicorn/__init__.py'>
  File "/usr/local/python3/lib/python3.8/site-packages/uvicorn/main.py", line 463, in run
    server.run()
    │      └ <function Server.run at 0x7f1bd5af5670>
    └ <uvicorn.server.Server object at 0x7f1bb89d3be0>
  File "/usr/local/python3/lib/python3.8/site-packages/uvicorn/server.py", line 60, in run
    return asyncio.run(self.serve(sockets=sockets))
           │       │   │    │             └ None
           │       │   │    └ <function Server.serve at 0x7f1bd5af5700>
           │       │   └ <uvicorn.server.Server object at 0x7f1bb89d3be0>
           │       └ <function run at 0x7f1bdb5400d0>
           └ <module 'asyncio' from '/usr/local/python3/lib/python3.8/asyncio/__init__.py'>
  File "/usr/local/python3/lib/python3.8/asyncio/runners.py", line 43, in run
    return loop.run_until_complete(main)
           │    │                  └ <coroutine object Server.serve at 0x7f1bb89e5940>
           │    └ <method 'run_until_complete' of 'uvloop.loop.Loop' objects>
           └ <uvloop.Loop running=True closed=False debug=False>
> File "/usr/local/python3/lib/python3.8/site-packages/nonebot/message.py", line 227, in _run_matcher
    await asyncio.gather(*coros)
          │       │       └ [<coroutine object _run_coro_with_catch at 0x7f1bb2527b40>]
          │       └ <function gather at 0x7f1bd9364c10>
          └ <module 'asyncio' from '/usr/local/python3/lib/python3.8/asyncio/__init__.py'>
  File "/usr/local/python3/lib/python3.8/site-packages/nonebot/message.py", line 115, in _run_coro_with_catch
    return await coro
                 └ <coroutine object Dependent.__call__ at 0x7f1bb2527ec0>
  File "/usr/local/python3/lib/python3.8/site-packages/nonebot/dependencies/__init__.py", line 92, in __call__
    return await self.call(**values)
                 │    │      └ {'exception': <ActionFailed data=None, echo={'seq': 145}, msg=SEND_MSG_API_ERROR, retcode=100, status=failed, wording=请参考 go-...
                 │    └ <function _track_error at 0x7f1bc9bd3d30>
                 └ <Dependent call=<function _track_error at 0x7f1bc9bd3d30>, params=[ModelField(name='exception', type=Optional[Exception], req...
  File "/usr/local/python3/lib/python3.8/site-packages/ATRI/exceptions.py", line 115, in _track_error
    await bot.send_private_msg(user_id=superusers, message=msg)
          │                            │                   └ '呜——出错了...追踪: aKAGryIH'
          │                            └ '1234567890'
          └ <nonebot.adapters.onebot.v11.bot.Bot object at 0x7f1bb3d9ae20>
  File "/usr/local/python3/lib/python3.8/site-packages/nonebot/adapters/onebot/v11/bot.py", line 208, in call_api
    return await super().call_api(api, **data)
                                  │      └ {'user_id': '1234567890', 'message': '呜——出错了...追踪: aKAGryIH'}
                                  └ 'send_private_msg'
  File "/usr/local/python3/lib/python3.8/site-packages/nonebot/internal/adapter/bot.py", line 117, in call_api
    raise exception
          └ <ActionFailed data=None, echo={'seq': 147}, msg=SEND_MSG_API_ERROR, retcode=100, status=failed, wording=请参考 go-cqhttp 端输出>
  File "/usr/local/python3/lib/python3.8/site-packages/nonebot/internal/adapter/bot.py", line 94, in call_api
    result = await self.adapter._call_api(self, api, **data)
                   │    │       │         │     │      └ {'user_id': '1234567890', 'message': '呜——出错了...追踪: aKAGryIH'}
                   │    │       │         │     └ 'send_private_msg'
                   │    │       │         └ <nonebot.adapters.onebot.v11.bot.Bot object at 0x7f1bb3d9ae20>
                   │    │       └ <function Adapter._call_api at 0x7f1bd5c13b80>
                   │    └ <nonebot.adapters.onebot.v11.adapter.Adapter object at 0x7f1bd5cffa90>
                   └ <nonebot.adapters.onebot.v11.bot.Bot object at 0x7f1bb3d9ae20>
  File "/usr/local/python3/lib/python3.8/site-packages/nonebot/adapters/onebot/v11/adapter.py", line 107, in _call_api
    return _handle_api_result(
           └ <function _handle_api_result at 0x7f1bd5ca1310>
  File "/usr/local/python3/lib/python3.8/site-packages/nonebot/adapters/onebot/v11/utils.py", line 81, in _handle_api_result
    raise ActionFailed(**result)
          │              └ {'data': None, 'echo': {'seq': 147}, 'msg': 'SEND_MSG_API_ERROR', 'retcode': 100, 'status': 'failed', 'wording': '请参考 go-cqht...
          └ <class 'nonebot.adapters.onebot.v11.exception.ActionFailed'>

nonebot.adapters.onebot.v11.exception.ActionFailed: <ActionFailed data=None, echo={'seq': 147}, msg=SEND_MSG_API_ERROR, retcode=100, status=failed, wording=请参考 go-cqhttp 端输出>
[36mATRI[0m | 03-03 15:19:54 | ERROR nonebot >> Running matcher <Matcher from src.plugins.nonebot_plugin_russian, type=message, priority=5, temp=False> failed.
Traceback (most recent call last):

  File "/usr/bin/nb", line 8, in <module>
    sys.exit(main())
    │   │    └ <ClickAliasedGroup main>
    │   └ <built-in function exit>
    └ <module 'sys' (built-in)>
  File "/usr/local/python3/lib/python3.8/site-packages/click/core.py", line 1128, in __call__
    return self.main(*args, **kwargs)
           │    │     │       └ {}
           │    │     └ ()
           │    └ <function BaseCommand.main at 0x7f1bdecad040>
           └ <ClickAliasedGroup main>
  File "/usr/local/python3/lib/python3.8/site-packages/click/core.py", line 1053, in main
    rv = self.invoke(ctx)
         │    │      └ <click.core.Context object at 0x7f1be6e21130>
         │    └ <function MultiCommand.invoke at 0x7f1bdecb10d0>
         └ <ClickAliasedGroup main>
  File "/usr/local/python3/lib/python3.8/site-packages/click/core.py", line 1659, in invoke
    return _process_result(sub_ctx.command.invoke(sub_ctx))
           │               │       │       │      └ <click.core.Context object at 0x7f1be6e26ca0>
           │               │       │       └ <function Command.invoke at 0x7f1bdecadaf0>
           │               │       └ <ClickAliasedCommand run>
           │               └ <click.core.Context object at 0x7f1be6e26ca0>
           └ <function MultiCommand.invoke.<locals>._process_result at 0x7f1bdf4f9a60>
  File "/usr/local/python3/lib/python3.8/site-packages/click/core.py", line 1395, in invoke
    return ctx.invoke(self.callback, **ctx.params)
           │   │      │    │           │   └ {'file': 'bot.py', 'app': 'app'}
           │   │      │    │           └ <click.core.Context object at 0x7f1be6e26ca0>
           │   │      │    └ <function run at 0x7f1bd5cf95e0>
           │   │      └ <ClickAliasedCommand run>
           │   └ <function Context.invoke at 0x7f1bdef2a8b0>
           └ <click.core.Context object at 0x7f1be6e26ca0>
  File "/usr/local/python3/lib/python3.8/site-packages/click/core.py", line 754, in invoke
    return __callback(*args, **kwargs)
                       │       └ {'file': 'bot.py', 'app': 'app'}
                       └ ()
  File "/usr/local/python3/lib/python3.8/site-packages/nb_cli/commands/main.py", line 30, in run
    run_bot(file, app)
    │       │     └ 'app'
    │       └ 'bot.py'
    └ <function run_bot at 0x7f1bd5ce93a0>
  File "/usr/local/python3/lib/python3.8/site-packages/nb_cli/handlers/deploy.py", line 24, in run_bot
    nonebot.run(app=f"{module_name}:{app}")
    │       └ <function run at 0x7f1bd7df2550>
    └ <module 'nonebot' from '/usr/local/python3/lib/python3.8/site-packages/nonebot/__init__.py'>
  File "/usr/local/python3/lib/python3.8/site-packages/nonebot/__init__.py", line 258, in run
    get_driver().run(*args, **kwargs)
    │                 │       └ {'app': 'bot:app'}
    │                 └ ()
    └ <function get_driver at 0x7f1bd7df20d0>
  File "/usr/local/python3/lib/python3.8/site-packages/nonebot/drivers/fastapi.py", line 168, in run
    uvicorn.run(
    │       └ <function run at 0x7f1bd5af5280>
    └ <module 'uvicorn' from '/usr/local/python3/lib/python3.8/site-packages/uvicorn/__init__.py'>
  File "/usr/local/python3/lib/python3.8/site-packages/uvicorn/main.py", line 463, in run
    server.run()
    │      └ <function Server.run at 0x7f1bd5af5670>
    └ <uvicorn.server.Server object at 0x7f1bb89d3be0>
  File "/usr/local/python3/lib/python3.8/site-packages/uvicorn/server.py", line 60, in run
    return asyncio.run(self.serve(sockets=sockets))
           │       │   │    │             └ None
           │       │   │    └ <function Server.serve at 0x7f1bd5af5700>
           │       │   └ <uvicorn.server.Server object at 0x7f1bb89d3be0>
           │       └ <function run at 0x7f1bdb5400d0>
           └ <module 'asyncio' from '/usr/local/python3/lib/python3.8/asyncio/__init__.py'>
  File "/usr/local/python3/lib/python3.8/asyncio/runners.py", line 43, in run
    return loop.run_until_complete(main)
           │    │                  └ <coroutine object Server.serve at 0x7f1bb89e5940>
           │    └ <method 'run_until_complete' of 'uvloop.loop.Loop' objects>
           └ <uvloop.Loop running=True closed=False debug=False>
  File "/usr/local/python3/lib/python3.8/site-packages/nonebot/message.py", line 153, in _check_matcher
    await _run_matcher(Matcher, bot, event, state, stack, dependency_cache)
          │            │        │    │      │      │      └ {<function _event_to_me at 0x7f1bd7e14c10>: <Task finished name='Task-405001' coro=<_event_to_me() done, defined at /usr/loca...
          │            │        │    │      │      └ <contextlib.AsyncExitStack object at 0x7f1b988fd8e0>
          │            │        │    │      └ {'_prefix': {'command': ('lottery',), 'raw_command': '/lottery', 'command_arg': []}}
          │            │        │    └ GroupMessageEvent(time=1646291988, self_id=507346814, post_type='message', sub_type='normal', user_id=963046537, message_type...
          │            │        └ <nonebot.adapters.onebot.v11.bot.Bot object at 0x7f1bb3d9ae20>
          │            └ <Matcher from src.plugins.nonebot_plugin_russian, type=message, priority=5, temp=False>
          └ <function _run_matcher at 0x7f1bd5c13280>
> File "/usr/local/python3/lib/python3.8/site-packages/nonebot/message.py", line 202, in _run_matcher
    await matcher.run(bot, event, state, stack, dependency_cache)
          │       │   │    │      │      │      └ {<function _event_to_me at 0x7f1bd7e14c10>: <Task finished name='Task-405001' coro=<_event_to_me() done, defined at /usr/loca...
          │       │   │    │      │      └ <contextlib.AsyncExitStack object at 0x7f1b988fd8e0>
          │       │   │    │      └ {'_prefix': {'command': ('lottery',), 'raw_command': '/lottery', 'command_arg': []}}
          │       │   │    └ GroupMessageEvent(time=1646291988, self_id=507346814, post_type='message', sub_type='normal', user_id=963046537, message_type...
          │       │   └ <nonebot.adapters.onebot.v11.bot.Bot object at 0x7f1bb3d9ae20>
          │       └ <function Matcher.run at 0x7f1bd7e14790>
          └ <Matcher from src.plugins.nonebot_plugin_russian, type=message, priority=5, temp=False>
  File "/usr/local/python3/lib/python3.8/site-packages/nonebot/internal/matcher.py", line 668, in run
    await self.simple_run(bot, event, state, stack, dependency_cache)
          │    │          │    │      │      │      └ {<function _event_to_me at 0x7f1bd7e14c10>: <Task finished name='Task-405001' coro=<_event_to_me() done, defined at /usr/loca...
          │    │          │    │      │      └ <contextlib.AsyncExitStack object at 0x7f1b988fd8e0>
          │    │          │    │      └ {'_prefix': {'command': ('lottery',), 'raw_command': '/lottery', 'command_arg': []}}
          │    │          │    └ GroupMessageEvent(time=1646291988, self_id=507346814, post_type='message', sub_type='normal', user_id=963046537, message_type...
          │    │          └ <nonebot.adapters.onebot.v11.bot.Bot object at 0x7f1bb3d9ae20>
          │    └ <function Matcher.simple_run at 0x7f1bd7e14700>
          └ <Matcher from src.plugins.nonebot_plugin_russian, type=message, priority=5, temp=False>
  File "/usr/local/python3/lib/python3.8/site-packages/nonebot/internal/matcher.py", line 635, in simple_run
    await handler(
          └ <Dependent call=<function _ at 0x7f1bc9da5430>, params=[ModelField(name='event', type=GroupMessageEvent, required=True), Mode...
  File "/usr/local/python3/lib/python3.8/site-packages/nonebot/dependencies/__init__.py", line 92, in __call__
    return await self.call(**values)
                 │    │      └ {'event': GroupMessageEvent(time=1646291988, self_id=507346814, post_type='message', sub_type='normal', user_id=963046537, me...
                 │    └ <function _ at 0x7f1bc9da5430>
                 └ <Dependent call=<function _ at 0x7f1bc9da5430>, params=[ModelField(name='event', type=GroupMessageEvent, required=True), Mode...

  File "./src/plugins/nonebot_plugin_russian/__init__.py", line 334, in _
    await lottery.send(message=msg, at_sender=True)
          │       │            └ '\n💸 Successfully bought 1 lottery ticket using 50 coins.\n🎉 YOU WON!!!!! 180.0 coins had been transferred to your pocket.'
          │       └ <classmethod object at 0x7f1bd7e0c6d0>
          └ <Matcher from src.plugins.nonebot_plugin_russian, type=message, priority=5, temp=False>

  File "/usr/local/python3/lib/python3.8/site-packages/nonebot/internal/matcher.py", line 449, in send
    return await bot.send(event=event, message=_message, **kwargs)
                 │   │          │              │           └ {'at_sender': True}
                 │   │          │              └ '\n💸 Successfully bought 1 lottery ticket using 50 coins.\n🎉 YOU WON!!!!! 180.0 coins had been transferred to your pocket.'
                 │   │          └ GroupMessageEvent(time=1646291988, self_id=507346814, post_type='message', sub_type='normal', user_id=963046537, message_type...
                 │   └ <function Bot.send at 0x7f1bd5c13790>
                 └ <nonebot.adapters.onebot.v11.bot.Bot object at 0x7f1bb3d9ae20>
  File "/usr/local/python3/lib/python3.8/site-packages/nonebot/adapters/onebot/v11/bot.py", line 247, in send
    return await self.__class__.send_handler(self, event, message, **kwargs)
                 │    │                      │     │      │          └ {'at_sender': True}
                 │    │                      │     │      └ '\n💸 Successfully bought 1 lottery ticket using 50 coins.\n🎉 YOU WON!!!!! 180.0 coins had been transferred to your pocket.'
                 │    │                      │     └ GroupMessageEvent(time=1646291988, self_id=507346814, post_type='message', sub_type='normal', user_id=963046537, message_type...
                 │    │                      └ <nonebot.adapters.onebot.v11.bot.Bot object at 0x7f1bb3d9ae20>
                 │    └ <attribute '__class__' of 'object' objects>
                 └ <nonebot.adapters.onebot.v11.bot.Bot object at 0x7f1bb3d9ae20>
  File "/usr/local/python3/lib/python3.8/site-packages/nonebot/adapters/onebot/v11/bot.py", line 175, in send
    return await bot.send_msg(**params)
                 │              └ {'user_id': 963046537, 'group_id': 937760225, 'message_type': 'group', 'message': [MessageSegment(type='at', data={'qq': '963...
                 └ <nonebot.adapters.onebot.v11.bot.Bot object at 0x7f1bb3d9ae20>
  File "/usr/local/python3/lib/python3.8/site-packages/nonebot/adapters/onebot/v11/bot.py", line 208, in call_api
    return await super().call_api(api, **data)
                                  │      └ {'user_id': 963046537, 'group_id': 937760225, 'message_type': 'group', 'message': [MessageSegment(type='at', data={'qq': '963...
                                  └ 'send_msg'
  File "/usr/local/python3/lib/python3.8/site-packages/nonebot/internal/adapter/bot.py", line 117, in call_api
    raise exception
          └ <ActionFailed data=None, echo={'seq': 155}, msg=SEND_MSG_API_ERROR, retcode=100, status=failed, wording=请参考 go-cqhttp 端输出>
  File "/usr/local/python3/lib/python3.8/site-packages/nonebot/internal/adapter/bot.py", line 94, in call_api
    result = await self.adapter._call_api(self, api, **data)
                   │    │       │         │     │      └ {'user_id': 963046537, 'group_id': 937760225, 'message_type': 'group', 'message': [MessageSegment(type='at', data={'qq': '963...
                   │    │       │         │     └ 'send_msg'
                   │    │       │         └ <nonebot.adapters.onebot.v11.bot.Bot object at 0x7f1bb3d9ae20>
                   │    │       └ <function Adapter._call_api at 0x7f1bd5c13b80>
                   │    └ <nonebot.adapters.onebot.v11.adapter.Adapter object at 0x7f1bd5cffa90>
                   └ <nonebot.adapters.onebot.v11.bot.Bot object at 0x7f1bb3d9ae20>
  File "/usr/local/python3/lib/python3.8/site-packages/nonebot/adapters/onebot/v11/adapter.py", line 107, in _call_api
    return _handle_api_result(
           └ <function _handle_api_result at 0x7f1bd5ca1310>
  File "/usr/local/python3/lib/python3.8/site-packages/nonebot/adapters/onebot/v11/utils.py", line 81, in _handle_api_result
    raise ActionFailed(**result)
          │              └ {'data': None, 'echo': {'seq': 155}, 'msg': 'SEND_MSG_API_ERROR', 'retcode': 100, 'status': 'failed', 'wording': '请参考 go-cqht...
          └ <class 'nonebot.adapters.onebot.v11.exception.ActionFailed'>

nonebot.adapters.onebot.v11.exception.ActionFailed: <ActionFailed data=None, echo={'seq': 155}, msg=SEND_MSG_API_ERROR, retcode=100, status=failed, wording=请参考 go-cqhttp 端输出>
[36mATRI[0m | 03-03 15:19:54 | ERROR nonebot >> Error when running RunPostProcessors
Traceback (most recent call last):

  File "/usr/bin/nb", line 8, in <module>
    sys.exit(main())
    │   │    └ <ClickAliasedGroup main>
    │   └ <built-in function exit>
    └ <module 'sys' (built-in)>
  File "/usr/local/python3/lib/python3.8/site-packages/click/core.py", line 1128, in __call__
    return self.main(*args, **kwargs)
           │    │     │       └ {}
           │    │     └ ()
           │    └ <function BaseCommand.main at 0x7f1bdecad040>
           └ <ClickAliasedGroup main>
  File "/usr/local/python3/lib/python3.8/site-packages/click/core.py", line 1053, in main
    rv = self.invoke(ctx)
         │    │      └ <click.core.Context object at 0x7f1be6e21130>
         │    └ <function MultiCommand.invoke at 0x7f1bdecb10d0>
         └ <ClickAliasedGroup main>
  File "/usr/local/python3/lib/python3.8/site-packages/click/core.py", line 1659, in invoke
    return _process_result(sub_ctx.command.invoke(sub_ctx))
           │               │       │       │      └ <click.core.Context object at 0x7f1be6e26ca0>
           │               │       │       └ <function Command.invoke at 0x7f1bdecadaf0>
           │               │       └ <ClickAliasedCommand run>
           │               └ <click.core.Context object at 0x7f1be6e26ca0>
           └ <function MultiCommand.invoke.<locals>._process_result at 0x7f1bdf4f9a60>
  File "/usr/local/python3/lib/python3.8/site-packages/click/core.py", line 1395, in invoke
    return ctx.invoke(self.callback, **ctx.params)
           │   │      │    │           │   └ {'file': 'bot.py', 'app': 'app'}
           │   │      │    │           └ <click.core.Context object at 0x7f1be6e26ca0>
           │   │      │    └ <function run at 0x7f1bd5cf95e0>
           │   │      └ <ClickAliasedCommand run>
           │   └ <function Context.invoke at 0x7f1bdef2a8b0>
           └ <click.core.Context object at 0x7f1be6e26ca0>
  File "/usr/local/python3/lib/python3.8/site-packages/click/core.py", line 754, in invoke
    return __callback(*args, **kwargs)
                       │       └ {'file': 'bot.py', 'app': 'app'}
                       └ ()
  File "/usr/local/python3/lib/python3.8/site-packages/nb_cli/commands/main.py", line 30, in run
    run_bot(file, app)
    │       │     └ 'app'
    │       └ 'bot.py'
    └ <function run_bot at 0x7f1bd5ce93a0>
  File "/usr/local/python3/lib/python3.8/site-packages/nb_cli/handlers/deploy.py", line 24, in run_bot
    nonebot.run(app=f"{module_name}:{app}")
    │       └ <function run at 0x7f1bd7df2550>
    └ <module 'nonebot' from '/usr/local/python3/lib/python3.8/site-packages/nonebot/__init__.py'>
  File "/usr/local/python3/lib/python3.8/site-packages/nonebot/__init__.py", line 258, in run
    get_driver().run(*args, **kwargs)
    │                 │       └ {'app': 'bot:app'}
    │                 └ ()
    └ <function get_driver at 0x7f1bd7df20d0>
  File "/usr/local/python3/lib/python3.8/site-packages/nonebot/drivers/fastapi.py", line 168, in run
    uvicorn.run(
    │       └ <function run at 0x7f1bd5af5280>
    └ <module 'uvicorn' from '/usr/local/python3/lib/python3.8/site-packages/uvicorn/__init__.py'>
  File "/usr/local/python3/lib/python3.8/site-packages/uvicorn/main.py", line 463, in run
    server.run()
    │      └ <function Server.run at 0x7f1bd5af5670>
    └ <uvicorn.server.Server object at 0x7f1bb89d3be0>
  File "/usr/local/python3/lib/python3.8/site-packages/uvicorn/server.py", line 60, in run
    return asyncio.run(self.serve(sockets=sockets))
           │       │   │    │             └ None
           │       │   │    └ <function Server.serve at 0x7f1bd5af5700>
           │       │   └ <uvicorn.server.Server object at 0x7f1bb89d3be0>
           │       └ <function run at 0x7f1bdb5400d0>
           └ <module 'asyncio' from '/usr/local/python3/lib/python3.8/asyncio/__init__.py'>
  File "/usr/local/python3/lib/python3.8/asyncio/runners.py", line 43, in run
    return loop.run_until_complete(main)
           │    │                  └ <coroutine object Server.serve at 0x7f1bb89e5940>
           │    └ <method 'run_until_complete' of 'uvloop.loop.Loop' objects>
           └ <uvloop.Loop running=True closed=False debug=False>
> File "/usr/local/python3/lib/python3.8/site-packages/nonebot/message.py", line 227, in _run_matcher
    await asyncio.gather(*coros)
          │       │       └ [<coroutine object _run_coro_with_catch at 0x7f1b98875e40>]
          │       └ <function gather at 0x7f1bd9364c10>
          └ <module 'asyncio' from '/usr/local/python3/lib/python3.8/asyncio/__init__.py'>
  File "/usr/local/python3/lib/python3.8/site-packages/nonebot/message.py", line 115, in _run_coro_with_catch
    return await coro
                 └ <coroutine object Dependent.__call__ at 0x7f1b98875a40>
  File "/usr/local/python3/lib/python3.8/site-packages/nonebot/dependencies/__init__.py", line 92, in __call__
    return await self.call(**values)
                 │    │      └ {'exception': <ActionFailed data=None, echo={'seq': 155}, msg=SEND_MSG_API_ERROR, retcode=100, status=failed, wording=请参考 go-...
                 │    └ <function _track_error at 0x7f1bc9bd3d30>
                 └ <Dependent call=<function _track_error at 0x7f1bc9bd3d30>, params=[ModelField(name='exception', type=Optional[Exception], req...
  File "/usr/local/python3/lib/python3.8/site-packages/ATRI/exceptions.py", line 115, in _track_error
    await bot.send_private_msg(user_id=superusers, message=msg)
          │                            │                   └ '呜——出错了...追踪: 8zoEP1s6'
          │                            └ '1234567890'
          └ <nonebot.adapters.onebot.v11.bot.Bot object at 0x7f1bb3d9ae20>
  File "/usr/local/python3/lib/python3.8/site-packages/nonebot/adapters/onebot/v11/bot.py", line 208, in call_api
    return await super().call_api(api, **data)
                                  │      └ {'user_id': '1234567890', 'message': '呜——出错了...追踪: 8zoEP1s6'}
                                  └ 'send_private_msg'
  File "/usr/local/python3/lib/python3.8/site-packages/nonebot/internal/adapter/bot.py", line 117, in call_api
    raise exception
          └ <ActionFailed data=None, echo={'seq': 156}, msg=SEND_MSG_API_ERROR, retcode=100, status=failed, wording=请参考 go-cqhttp 端输出>
  File "/usr/local/python3/lib/python3.8/site-packages/nonebot/internal/adapter/bot.py", line 94, in call_api
    result = await self.adapter._call_api(self, api, **data)
                   │    │       │         │     │      └ {'user_id': '1234567890', 'message': '呜——出错了...追踪: 8zoEP1s6'}
                   │    │       │         │     └ 'send_private_msg'
                   │    │       │         └ <nonebot.adapters.onebot.v11.bot.Bot object at 0x7f1bb3d9ae20>
                   │    │       └ <function Adapter._call_api at 0x7f1bd5c13b80>
                   │    └ <nonebot.adapters.onebot.v11.adapter.Adapter object at 0x7f1bd5cffa90>
                   └ <nonebot.adapters.onebot.v11.bot.Bot object at 0x7f1bb3d9ae20>
  File "/usr/local/python3/lib/python3.8/site-packages/nonebot/adapters/onebot/v11/adapter.py", line 107, in _call_api
    return _handle_api_result(
           └ <function _handle_api_result at 0x7f1bd5ca1310>
  File "/usr/local/python3/lib/python3.8/site-packages/nonebot/adapters/onebot/v11/utils.py", line 81, in _handle_api_result
    raise ActionFailed(**result)
          │              └ {'data': None, 'echo': {'seq': 156}, 'msg': 'SEND_MSG_API_ERROR', 'retcode': 100, 'status': 'failed', 'wording': '请参考 go-cqht...
          └ <class 'nonebot.adapters.onebot.v11.exception.ActionFailed'>

nonebot.adapters.onebot.v11.exception.ActionFailed: <ActionFailed data=None, echo={'seq': 156}, msg=SEND_MSG_API_ERROR, retcode=100, status=failed, wording=请参考 go-cqhttp 端输出>
[36mATRI[0m | 03-03 17:42:05 | ERROR nonebot >> Running matcher <Matcher from src.plugins.nonebot_plugin_status, type=notice, priority=10, temp=False> failed.
Traceback (most recent call last):

  File "/usr/bin/nb", line 8, in <module>
    sys.exit(main())
    │   │    └ <ClickAliasedGroup main>
    │   └ <built-in function exit>
    └ <module 'sys' (built-in)>
  File "/usr/local/python3/lib/python3.8/site-packages/click/core.py", line 1128, in __call__
    return self.main(*args, **kwargs)
           │    │     │       └ {}
           │    │     └ ()
           │    └ <function BaseCommand.main at 0x7f1bdecad040>
           └ <ClickAliasedGroup main>
  File "/usr/local/python3/lib/python3.8/site-packages/click/core.py", line 1053, in main
    rv = self.invoke(ctx)
         │    │      └ <click.core.Context object at 0x7f1be6e21130>
         │    └ <function MultiCommand.invoke at 0x7f1bdecb10d0>
         └ <ClickAliasedGroup main>
  File "/usr/local/python3/lib/python3.8/site-packages/click/core.py", line 1659, in invoke
    return _process_result(sub_ctx.command.invoke(sub_ctx))
           │               │       │       │      └ <click.core.Context object at 0x7f1be6e26ca0>
           │               │       │       └ <function Command.invoke at 0x7f1bdecadaf0>
           │               │       └ <ClickAliasedCommand run>
           │               └ <click.core.Context object at 0x7f1be6e26ca0>
           └ <function MultiCommand.invoke.<locals>._process_result at 0x7f1bdf4f9a60>
  File "/usr/local/python3/lib/python3.8/site-packages/click/core.py", line 1395, in invoke
    return ctx.invoke(self.callback, **ctx.params)
           │   │      │    │           │   └ {'file': 'bot.py', 'app': 'app'}
           │   │      │    │           └ <click.core.Context object at 0x7f1be6e26ca0>
           │   │      │    └ <function run at 0x7f1bd5cf95e0>
           │   │      └ <ClickAliasedCommand run>
           │   └ <function Context.invoke at 0x7f1bdef2a8b0>
           └ <click.core.Context object at 0x7f1be6e26ca0>
  File "/usr/local/python3/lib/python3.8/site-packages/click/core.py", line 754, in invoke
    return __callback(*args, **kwargs)
                       │       └ {'file': 'bot.py', 'app': 'app'}
                       └ ()
  File "/usr/local/python3/lib/python3.8/site-packages/nb_cli/commands/main.py", line 30, in run
    run_bot(file, app)
    │       │     └ 'app'
    │       └ 'bot.py'
    └ <function run_bot at 0x7f1bd5ce93a0>
  File "/usr/local/python3/lib/python3.8/site-packages/nb_cli/handlers/deploy.py", line 24, in run_bot
    nonebot.run(app=f"{module_name}:{app}")
    │       └ <function run at 0x7f1bd7df2550>
    └ <module 'nonebot' from '/usr/local/python3/lib/python3.8/site-packages/nonebot/__init__.py'>
  File "/usr/local/python3/lib/python3.8/site-packages/nonebot/__init__.py", line 258, in run
    get_driver().run(*args, **kwargs)
    │                 │       └ {'app': 'bot:app'}
    │                 └ ()
    └ <function get_driver at 0x7f1bd7df20d0>
  File "/usr/local/python3/lib/python3.8/site-packages/nonebot/drivers/fastapi.py", line 168, in run
    uvicorn.run(
    │       └ <function run at 0x7f1bd5af5280>
    └ <module 'uvicorn' from '/usr/local/python3/lib/python3.8/site-packages/uvicorn/__init__.py'>
  File "/usr/local/python3/lib/python3.8/site-packages/uvicorn/main.py", line 463, in run
    server.run()
    │      └ <function Server.run at 0x7f1bd5af5670>
    └ <uvicorn.server.Server object at 0x7f1bb89d3be0>
  File "/usr/local/python3/lib/python3.8/site-packages/uvicorn/server.py", line 60, in run
    return asyncio.run(self.serve(sockets=sockets))
           │       │   │    │             └ None
           │       │   │    └ <function Server.serve at 0x7f1bd5af5700>
           │       │   └ <uvicorn.server.Server object at 0x7f1bb89d3be0>
           │       └ <function run at 0x7f1bdb5400d0>
           └ <module 'asyncio' from '/usr/local/python3/lib/python3.8/asyncio/__init__.py'>
  File "/usr/local/python3/lib/python3.8/asyncio/runners.py", line 43, in run
    return loop.run_until_complete(main)
           │    │                  └ <coroutine object Server.serve at 0x7f1bb89e5940>
           │    └ <method 'run_until_complete' of 'uvloop.loop.Loop' objects>
           └ <uvloop.Loop running=True closed=False debug=False>
  File "/usr/local/python3/lib/python3.8/site-packages/nonebot/message.py", line 153, in _check_matcher
    await _run_matcher(Matcher, bot, event, state, stack, dependency_cache)
          │            │        │    │      │      │      └ {}
          │            │        │    │      │      └ <contextlib.AsyncExitStack object at 0x7f1b988ef4f0>
          │            │        │    │      └ {'_prefix': {'command': None, 'raw_command': None, 'command_arg': None}}
          │            │        │    └ PokeNotifyEvent(time=1646300524, self_id=507346814, post_type='notice', notice_type='notify', sub_type='poke', user_id=256035...
          │            │        └ <nonebot.adapters.onebot.v11.bot.Bot object at 0x7f1bb3d9ae20>
          │            └ <Matcher from src.plugins.nonebot_plugin_status, type=notice, priority=10, temp=False>
          └ <function _run_matcher at 0x7f1bd5c13280>
> File "/usr/local/python3/lib/python3.8/site-packages/nonebot/message.py", line 202, in _run_matcher
    await matcher.run(bot, event, state, stack, dependency_cache)
          │       │   │    │      │      │      └ {}
          │       │   │    │      │      └ <contextlib.AsyncExitStack object at 0x7f1b988ef4f0>
          │       │   │    │      └ {'_prefix': {'command': None, 'raw_command': None, 'command_arg': None}}
          │       │   │    └ PokeNotifyEvent(time=1646300524, self_id=507346814, post_type='notice', notice_type='notify', sub_type='poke', user_id=256035...
          │       │   └ <nonebot.adapters.onebot.v11.bot.Bot object at 0x7f1bb3d9ae20>
          │       └ <function Matcher.run at 0x7f1bd7e14790>
          └ <Matcher from src.plugins.nonebot_plugin_status, type=notice, priority=10, temp=False>
  File "/usr/local/python3/lib/python3.8/site-packages/nonebot/internal/matcher.py", line 668, in run
    await self.simple_run(bot, event, state, stack, dependency_cache)
          │    │          │    │      │      │      └ {}
          │    │          │    │      │      └ <contextlib.AsyncExitStack object at 0x7f1b988ef4f0>
          │    │          │    │      └ {'_prefix': {'command': None, 'raw_command': None, 'command_arg': None}}
          │    │          │    └ PokeNotifyEvent(time=1646300524, self_id=507346814, post_type='notice', notice_type='notify', sub_type='poke', user_id=256035...
          │    │          └ <nonebot.adapters.onebot.v11.bot.Bot object at 0x7f1bb3d9ae20>
          │    └ <function Matcher.simple_run at 0x7f1bd7e14700>
          └ <Matcher from src.plugins.nonebot_plugin_status, type=notice, priority=10, temp=False>
  File "/usr/local/python3/lib/python3.8/site-packages/nonebot/internal/matcher.py", line 635, in simple_run
    await handler(
          └ <Dependent call=<function server_status at 0x7f1bd2a3a5e0>, params=[ModelField(name='matcher', type=Matcher, required=True)],...
  File "/usr/local/python3/lib/python3.8/site-packages/nonebot/dependencies/__init__.py", line 92, in __call__
    return await self.call(**values)
                 │    │      └ {'matcher': <Matcher from src.plugins.nonebot_plugin_status, type=notice, priority=10, temp=False>}
                 │    └ <function server_status at 0x7f1bd2a3a5e0>
                 └ <Dependent call=<function server_status at 0x7f1bd2a3a5e0>, params=[ModelField(name='matcher', type=Matcher, required=True)],...

  File "./src/plugins/nonebot_plugin_status/__init__.py", line 64, in server_status
    pic = await md_to_pic(md=data)
                │            └ ['CPU:', '  core1: 09%', '  core2: 04%', 'Memory: 81%', 'Disk:', '  /: 41%', '  /var/lib/docker/containers: 41%', '  /var/lib...
                └ <function md_to_pic at 0x7f1bd2a3a1f0>

  File "./src/plugins/nonebot_plugin_status/data_source.py", line 75, in md_to_pic
    md = markdown.markdown(
         │        └ <function markdown at 0x7f1bd4550790>
         └ <module 'markdown' from '/usr/local/python3/lib/python3.8/site-packages/markdown/__init__.py'>

  File "/usr/local/python3/lib/python3.8/site-packages/markdown/core.py", line 387, in markdown
    return md.convert(text)
           │  │       └ ['CPU:', '  core1: 09%', '  core2: 04%', 'Memory: 81%', 'Disk:', '  /: 41%', '  /var/lib/docker/containers: 41%', '  /var/lib...
           │  └ <function Markdown.convert at 0x7f1bd42a2790>
           └ <markdown.core.Markdown object at 0x7f1bb086ea60>
  File "/usr/local/python3/lib/python3.8/site-packages/markdown/core.py", line 248, in convert
    if not source.strip():
           └ ['CPU:', '  core1: 09%', '  core2: 04%', 'Memory: 81%', 'Disk:', '  /: 41%', '  /var/lib/docker/containers: 41%', '  /var/lib...

AttributeError: 'list' object has no attribute 'strip'
[36mATRI[0m | 03-03 17:42:06 | ERROR nonebot >> Error when running RunPostProcessors
Traceback (most recent call last):

  File "/usr/bin/nb", line 8, in <module>
    sys.exit(main())
    │   │    └ <ClickAliasedGroup main>
    │   └ <built-in function exit>
    └ <module 'sys' (built-in)>
  File "/usr/local/python3/lib/python3.8/site-packages/click/core.py", line 1128, in __call__
    return self.main(*args, **kwargs)
           │    │     │       └ {}
           │    │     └ ()
           │    └ <function BaseCommand.main at 0x7f1bdecad040>
           └ <ClickAliasedGroup main>
  File "/usr/local/python3/lib/python3.8/site-packages/click/core.py", line 1053, in main
    rv = self.invoke(ctx)
         │    │      └ <click.core.Context object at 0x7f1be6e21130>
         │    └ <function MultiCommand.invoke at 0x7f1bdecb10d0>
         └ <ClickAliasedGroup main>
  File "/usr/local/python3/lib/python3.8/site-packages/click/core.py", line 1659, in invoke
    return _process_result(sub_ctx.command.invoke(sub_ctx))
           │               │       │       │      └ <click.core.Context object at 0x7f1be6e26ca0>
           │               │       │       └ <function Command.invoke at 0x7f1bdecadaf0>
           │               │       └ <ClickAliasedCommand run>
           │               └ <click.core.Context object at 0x7f1be6e26ca0>
           └ <function MultiCommand.invoke.<locals>._process_result at 0x7f1bdf4f9a60>
  File "/usr/local/python3/lib/python3.8/site-packages/click/core.py", line 1395, in invoke
    return ctx.invoke(self.callback, **ctx.params)
           │   │      │    │           │   └ {'file': 'bot.py', 'app': 'app'}
           │   │      │    │           └ <click.core.Context object at 0x7f1be6e26ca0>
           │   │      │    └ <function run at 0x7f1bd5cf95e0>
           │   │      └ <ClickAliasedCommand run>
           │   └ <function Context.invoke at 0x7f1bdef2a8b0>
           └ <click.core.Context object at 0x7f1be6e26ca0>
  File "/usr/local/python3/lib/python3.8/site-packages/click/core.py", line 754, in invoke
    return __callback(*args, **kwargs)
                       │       └ {'file': 'bot.py', 'app': 'app'}
                       └ ()
  File "/usr/local/python3/lib/python3.8/site-packages/nb_cli/commands/main.py", line 30, in run
    run_bot(file, app)
    │       │     └ 'app'
    │       └ 'bot.py'
    └ <function run_bot at 0x7f1bd5ce93a0>
  File "/usr/local/python3/lib/python3.8/site-packages/nb_cli/handlers/deploy.py", line 24, in run_bot
    nonebot.run(app=f"{module_name}:{app}")
    │       └ <function run at 0x7f1bd7df2550>
    └ <module 'nonebot' from '/usr/local/python3/lib/python3.8/site-packages/nonebot/__init__.py'>
  File "/usr/local/python3/lib/python3.8/site-packages/nonebot/__init__.py", line 258, in run
    get_driver().run(*args, **kwargs)
    │                 │       └ {'app': 'bot:app'}
    │                 └ ()
    └ <function get_driver at 0x7f1bd7df20d0>
  File "/usr/local/python3/lib/python3.8/site-packages/nonebot/drivers/fastapi.py", line 168, in run
    uvicorn.run(
    │       └ <function run at 0x7f1bd5af5280>
    └ <module 'uvicorn' from '/usr/local/python3/lib/python3.8/site-packages/uvicorn/__init__.py'>
  File "/usr/local/python3/lib/python3.8/site-packages/uvicorn/main.py", line 463, in run
    server.run()
    │      └ <function Server.run at 0x7f1bd5af5670>
    └ <uvicorn.server.Server object at 0x7f1bb89d3be0>
  File "/usr/local/python3/lib/python3.8/site-packages/uvicorn/server.py", line 60, in run
    return asyncio.run(self.serve(sockets=sockets))
           │       │   │    │             └ None
           │       │   │    └ <function Server.serve at 0x7f1bd5af5700>
           │       │   └ <uvicorn.server.Server object at 0x7f1bb89d3be0>
           │       └ <function run at 0x7f1bdb5400d0>
           └ <module 'asyncio' from '/usr/local/python3/lib/python3.8/asyncio/__init__.py'>
  File "/usr/local/python3/lib/python3.8/asyncio/runners.py", line 43, in run
    return loop.run_until_complete(main)
           │    │                  └ <coroutine object Server.serve at 0x7f1bb89e5940>
           │    └ <method 'run_until_complete' of 'uvloop.loop.Loop' objects>
           └ <uvloop.Loop running=True closed=False debug=False>
> File "/usr/local/python3/lib/python3.8/site-packages/nonebot/message.py", line 227, in _run_matcher
    await asyncio.gather(*coros)
          │       │       └ [<coroutine object _run_coro_with_catch at 0x7f1bb2527740>]
          │       └ <function gather at 0x7f1bd9364c10>
          └ <module 'asyncio' from '/usr/local/python3/lib/python3.8/asyncio/__init__.py'>
  File "/usr/local/python3/lib/python3.8/site-packages/nonebot/message.py", line 115, in _run_coro_with_catch
    return await coro
                 └ <coroutine object Dependent.__call__ at 0x7f1b98871f40>
  File "/usr/local/python3/lib/python3.8/site-packages/nonebot/dependencies/__init__.py", line 92, in __call__
    return await self.call(**values)
                 │    │      └ {'exception': AttributeError("'list' object has no attribute 'strip'"), 'bot': <nonebot.adapters.onebot.v11.bot.Bot object at...
                 │    └ <function _track_error at 0x7f1bc9bd3d30>
                 └ <Dependent call=<function _track_error at 0x7f1bc9bd3d30>, params=[ModelField(name='exception', type=Optional[Exception], req...
  File "/usr/local/python3/lib/python3.8/site-packages/ATRI/exceptions.py", line 115, in _track_error
    await bot.send_private_msg(user_id=superusers, message=msg)
          │                            │                   └ '呜——出错了...追踪: Vc3a4UDn'
          │                            └ '1234567890'
          └ <nonebot.adapters.onebot.v11.bot.Bot object at 0x7f1bb3d9ae20>
  File "/usr/local/python3/lib/python3.8/site-packages/nonebot/adapters/onebot/v11/bot.py", line 208, in call_api
    return await super().call_api(api, **data)
                                  │      └ {'user_id': '1234567890', 'message': '呜——出错了...追踪: Vc3a4UDn'}
                                  └ 'send_private_msg'
  File "/usr/local/python3/lib/python3.8/site-packages/nonebot/internal/adapter/bot.py", line 117, in call_api
    raise exception
          └ <ActionFailed data=None, echo={'seq': 313}, msg=SEND_MSG_API_ERROR, retcode=100, status=failed, wording=请参考 go-cqhttp 端输出>
  File "/usr/local/python3/lib/python3.8/site-packages/nonebot/internal/adapter/bot.py", line 94, in call_api
    result = await self.adapter._call_api(self, api, **data)
                   │    │       │         │     │      └ {'user_id': '1234567890', 'message': '呜——出错了...追踪: Vc3a4UDn'}
                   │    │       │         │     └ 'send_private_msg'
                   │    │       │         └ <nonebot.adapters.onebot.v11.bot.Bot object at 0x7f1bb3d9ae20>
                   │    │       └ <function Adapter._call_api at 0x7f1bd5c13b80>
                   │    └ <nonebot.adapters.onebot.v11.adapter.Adapter object at 0x7f1bd5cffa90>
                   └ <nonebot.adapters.onebot.v11.bot.Bot object at 0x7f1bb3d9ae20>
  File "/usr/local/python3/lib/python3.8/site-packages/nonebot/adapters/onebot/v11/adapter.py", line 107, in _call_api
    return _handle_api_result(
           └ <function _handle_api_result at 0x7f1bd5ca1310>
  File "/usr/local/python3/lib/python3.8/site-packages/nonebot/adapters/onebot/v11/utils.py", line 81, in _handle_api_result
    raise ActionFailed(**result)
          │              └ {'data': None, 'echo': {'seq': 313}, 'msg': 'SEND_MSG_API_ERROR', 'retcode': 100, 'status': 'failed', 'wording': '请参考 go-cqht...
          └ <class 'nonebot.adapters.onebot.v11.exception.ActionFailed'>

nonebot.adapters.onebot.v11.exception.ActionFailed: <ActionFailed data=None, echo={'seq': 313}, msg=SEND_MSG_API_ERROR, retcode=100, status=failed, wording=请参考 go-cqhttp 端输出>
[36mATRI[0m | 03-03 17:55:49 | WARNING nonebot >> OneBot V11 | WebSocket for Bot 507346814 closed by peer
