{
    "track_id": "0b1Cnhpr",
    "prompt": "Unknown ERROR->ActionFailed",
    "time": "2022-03-13 16:22:37",
    "content": "Traceback (most recent call last):\n  File \"/usr/local/python3/lib/python3.8/site-packages/ATRI/exceptions.py\", line 102, in _track_error\n    raise exception\n  File \"/usr/local/python3/lib/python3.8/site-packages/nonebot/message.py\", line 202, in _run_matcher\n    await matcher.run(bot, event, state, stack, dependency_cache)\n  File \"/usr/local/python3/lib/python3.8/site-packages/nonebot/internal/matcher.py\", line 668, in run\n    await self.simple_run(bot, event, state, stack, dependency_cache)\n  File \"/usr/local/python3/lib/python3.8/site-packages/nonebot/internal/matcher.py\", line 635, in simple_run\n    await handler(\n  File \"/usr/local/python3/lib/python3.8/site-packages/nonebot/dependencies/__init__.py\", line 92, in __call__\n    return await self.call(**values)\n  File \"./src/plugins/nonebot_plugin_repeater/__init__.py\", line 66, in repeater\n    await bot.send(event, data)\n  File \"/usr/local/python3/lib/python3.8/site-packages/nonebot/adapters/onebot/v11/bot.py\", line 247, in send\n    return await self.__class__.send_handler(self, event, message, **kwargs)\n  File \"/usr/local/python3/lib/python3.8/site-packages/nonebot/adapters/onebot/v11/bot.py\", line 175, in send\n    return await bot.send_msg(**params)\n  File \"/usr/local/python3/lib/python3.8/site-packages/nonebot/adapters/onebot/v11/bot.py\", line 208, in call_api\n    return await super().call_api(api, **data)\n  File \"/usr/local/python3/lib/python3.8/site-packages/nonebot/internal/adapter/bot.py\", line 117, in call_api\n    raise exception\n  File \"/usr/local/python3/lib/python3.8/site-packages/nonebot/internal/adapter/bot.py\", line 94, in call_api\n    result = await self.adapter._call_api(self, api, **data)\n  File \"/usr/local/python3/lib/python3.8/site-packages/nonebot/adapters/onebot/v11/adapter.py\", line 107, in _call_api\n    return _handle_api_result(\n  File \"/usr/local/python3/lib/python3.8/site-packages/nonebot/adapters/onebot/v11/utils.py\", line 81, in _handle_api_result\n    raise ActionFailed(**result)\nnonebot.adapters.onebot.v11.exception.ActionFailed: <ActionFailed data=None, echo={'seq': 25}, msg=SEND_MSG_API_ERROR, retcode=100, status=failed, wording=\u8bf7\u53c2\u8003 go-cqhttp \u7aef\u8f93\u51fa>\n"
}