{
    "track_id": "8PBp6iXG",
    "prompt": "Unknown ERROR->APIError",
    "time": "2022-03-11 09:33:46",
    "content": "Traceback (most recent call last):\n  File \"/usr/local/python3/lib/python3.8/site-packages/ATRI/exceptions.py\", line 102, in _track_error\n    raise exception\n  File \"/usr/local/python3/lib/python3.8/site-packages/nonebot/message.py\", line 202, in _run_matcher\n    await matcher.run(bot, event, state, stack, dependency_cache)\n  File \"/usr/local/python3/lib/python3.8/site-packages/nonebot/internal/matcher.py\", line 668, in run\n    await self.simple_run(bot, event, state, stack, dependency_cache)\n  File \"/usr/local/python3/lib/python3.8/site-packages/nonebot/internal/matcher.py\", line 635, in simple_run\n    await handler(\n  File \"/usr/local/python3/lib/python3.8/site-packages/nonebot/dependencies/__init__.py\", line 92, in __call__\n    return await self.call(**values)\n  File \"./src/plugins/nonebot_plugin_heweather/__init__.py\", line 33, in _\n    await w_data.load_data()\n  File \"./src/plugins/nonebot_plugin_heweather/weather_data.py\", line 54, in load_data\n    self.city_id = await self._get_city_id()\n  File \"./src/plugins/nonebot_plugin_heweather/weather_data.py\", line 74, in _get_city_id\n    raise APIError(\"\u9519\u8bef! \u9519\u8bef\u4ee3\u7801: {}\".format(res[\"code\"]) + self.__reference)\nsrc.plugins.nonebot_plugin_heweather.weather_data.APIError: \u9519\u8bef! \u9519\u8bef\u4ee3\u7801: 404\n\u8bf7\u53c2\u8003: https://dev.qweather.com/docs/start/status-code/\n"
}