{
    "track_id": "AFYRJkvn",
    "prompt": "Unknown ERROR->NetworkError",
    "time": "2022-03-15 11:42:05",
    "content": "Traceback (most recent call last):\n  File \"/usr/local/python3/lib/python3.8/site-packages/ATRI/exceptions.py\", line 102, in _track_error\n    raise exception\n  File \"/usr/local/python3/lib/python3.8/site-packages/nonebot/message.py\", line 202, in _run_matcher\n    await matcher.run(bot, event, state, stack, dependency_cache)\n  File \"/usr/local/python3/lib/python3.8/site-packages/nonebot/internal/matcher.py\", line 668, in run\n    await self.simple_run(bot, event, state, stack, dependency_cache)\n  File \"/usr/local/python3/lib/python3.8/site-packages/nonebot/internal/matcher.py\", line 635, in simple_run\n    await handler(\n  File \"/usr/local/python3/lib/python3.8/site-packages/nonebot/dependencies/__init__.py\", line 92, in __call__\n    return await self.call(**values)\n  File \"./src/plugins/biliav/__init__.py\", line 29, in handle\n    await bot.send(event=event,message=rj)\n  File \"/usr/local/python3/lib/python3.8/site-packages/nonebot/adapters/onebot/v11/bot.py\", line 247, in send\n    return await self.__class__.send_handler(self, event, message, **kwargs)\n  File \"/usr/local/python3/lib/python3.8/site-packages/nonebot/adapters/onebot/v11/bot.py\", line 175, in send\n    return await bot.send_msg(**params)\n  File \"/usr/local/python3/lib/python3.8/site-packages/nonebot/adapters/onebot/v11/bot.py\", line 208, in call_api\n    return await super().call_api(api, **data)\n  File \"/usr/local/python3/lib/python3.8/site-packages/nonebot/internal/adapter/bot.py\", line 117, in call_api\n    raise exception\n  File \"/usr/local/python3/lib/python3.8/site-packages/nonebot/internal/adapter/bot.py\", line 94, in call_api\n    result = await self.adapter._call_api(self, api, **data)\n  File \"/usr/local/python3/lib/python3.8/site-packages/nonebot/adapters/onebot/v11/adapter.py\", line 108, in _call_api\n    await ResultStore.fetch(bot.self_id, seq, self.config.api_timeout)\n  File \"/usr/local/python3/lib/python3.8/site-packages/nonebot/adapters/onebot/v11/utils.py\", line 113, in fetch\n    raise NetworkError(\"WebSocket API call timeout\") from None\nnonebot.adapters.onebot.v11.exception.NetworkError: <NetWorkError message=WebSocket API call timeout>\n"
}