{
    "track_id": "hEA1RXxS",
    "prompt": "Unknown ERROR->IndexError",
    "time": "2022-03-17 20:36:57",
    "content": "Traceback (most recent call last):\n  File \"/root/Projects/Kori-Bot/Kori-bot/./ATRI/exceptions.py\", line 102, in _track_error\n    raise exception\n  File \"/usr/local/lib/python3.8/dist-packages/nonebot/message.py\", line 202, in _run_matcher\n    await matcher.run(bot, event, state, stack, dependency_cache)\n  File \"/usr/local/lib/python3.8/dist-packages/nonebot/internal/matcher.py\", line 668, in run\n    await self.simple_run(bot, event, state, stack, dependency_cache)\n  File \"/usr/local/lib/python3.8/dist-packages/nonebot/internal/matcher.py\", line 635, in simple_run\n    await handler(\n  File \"/usr/local/lib/python3.8/dist-packages/nonebot/dependencies/__init__.py\", line 92, in __call__\n    return await self.call(**values)\n  File \"/root/Projects/Kori-Bot/Kori-bot/./src/plugins/cp/__init__.py\", line 79, in _\n    await cp.send('\\n'+getMessage(name_list), at_sender=True)\n  File \"/root/Projects/Kori-Bot/Kori-bot/./src/plugins/cp/__init__.py\", line 49, in getMessage\n    .replace(\"<\u53d7>\", name_list[1])\nIndexError: list index out of range\n"
}