{
    "track_id": "QUTdvXSs",
    "prompt": "Unknown ERROR->ActionFailed",
    "time": "2022-03-11 20:16:15",
    "content": "Traceback (most recent call last):\n  File \"/usr/local/python3/lib/python3.8/site-packages/ATRI/exceptions.py\", line 102, in _track_error\n    raise exception\n  File \"/usr/local/python3/lib/python3.8/site-packages/nonebot/message.py\", line 202, in _run_matcher\n    await matcher.run(bot, event, state, stack, dependency_cache)\n  File \"/usr/local/python3/lib/python3.8/site-packages/nonebot/internal/matcher.py\", line 668, in run\n    await self.simple_run(bot, event, state, stack, dependency_cache)\n  File \"/usr/local/python3/lib/python3.8/site-packages/nonebot/internal/matcher.py\", line 635, in simple_run\n    await handler(\n  File \"/usr/local/python3/lib/python3.8/site-packages/nonebot/dependencies/__init__.py\", line 92, in __call__\n    return await self.call(**values)\n  File \"./src/plugins/nonebot_plugin_chess/__init__.py\", line 49, in _\n    await handle_chess(chess, event, argv)\n  File \"./src/plugins/nonebot_plugin_chess/__init__.py\", line 135, in handle_chess\n    await send('\u8f93\u5165\u201c\u4e94\u5b50\u68cb\u201d\u3001\u201c\u9ed1\u767d\u68cb\u201d\u3001\u201c\u56f4\u68cb\u201d\u5f00\u59cb\u4e00\u5c40\u6e38\u620f\u3002\\n\u518d\u8f93\u5165\u201c\u843d\u5b50 \u5b57\u6bcd+\u6570\u5b57\u201d\u4e0b\u68cb\uff0c\u5982\u201c\u843d\u5b50 A1\u201d')\n  File \"./src/plugins/nonebot_plugin_chess/__init__.py\", line 109, in send\n    await matcher.finish(msg)\n  File \"/usr/local/python3/lib/python3.8/site-packages/nonebot/internal/matcher.py\", line 464, in finish\n    await cls.send(message, **kwargs)\n  File \"/usr/local/python3/lib/python3.8/site-packages/nonebot/internal/matcher.py\", line 449, in send\n    return await bot.send(event=event, message=_message, **kwargs)\n  File \"/usr/local/python3/lib/python3.8/site-packages/nonebot/adapters/onebot/v11/bot.py\", line 247, in send\n    return await self.__class__.send_handler(self, event, message, **kwargs)\n  File \"/usr/local/python3/lib/python3.8/site-packages/nonebot/adapters/onebot/v11/bot.py\", line 175, in send\n    return await bot.send_msg(**params)\n  File \"/usr/local/python3/lib/python3.8/site-packages/nonebot/adapters/onebot/v11/bot.py\", line 208, in call_api\n    return await super().call_api(api, **data)\n  File \"/usr/local/python3/lib/python3.8/site-packages/nonebot/internal/adapter/bot.py\", line 117, in call_api\n    raise exception\n  File \"/usr/local/python3/lib/python3.8/site-packages/nonebot/internal/adapter/bot.py\", line 94, in call_api\n    result = await self.adapter._call_api(self, api, **data)\n  File \"/usr/local/python3/lib/python3.8/site-packages/nonebot/adapters/onebot/v11/adapter.py\", line 107, in _call_api\n    return _handle_api_result(\n  File \"/usr/local/python3/lib/python3.8/site-packages/nonebot/adapters/onebot/v11/utils.py\", line 81, in _handle_api_result\n    raise ActionFailed(**result)\nnonebot.adapters.onebot.v11.exception.ActionFailed: <ActionFailed data=None, echo={'seq': 206}, msg=SEND_MSG_API_ERROR, retcode=100, status=failed, wording=\u8bf7\u53c2\u8003 go-cqhttp \u7aef\u8f93\u51fa>\n"
}