{
    "track_id": "RL1Cnzjr",
    "prompt": "Unknown ERROR->TypeError",
    "time": "2022-03-16 15:12:00",
    "content": "Traceback (most recent call last):\n  File \"/root/Projects/Kori-Bot/Kori-bot/./ATRI/exceptions.py\", line 102, in _track_error\n    raise exception\n  File \"/usr/local/lib/python3.8/dist-packages/nonebot/message.py\", line 202, in _run_matcher\n    await matcher.run(bot, event, state, stack, dependency_cache)\n  File \"/usr/local/lib/python3.8/dist-packages/nonebot/internal/matcher.py\", line 668, in run\n    await self.simple_run(bot, event, state, stack, dependency_cache)\n  File \"/usr/local/lib/python3.8/dist-packages/nonebot/internal/matcher.py\", line 635, in simple_run\n    await handler(\n  File \"/usr/local/lib/python3.8/dist-packages/nonebot/dependencies/__init__.py\", line 92, in __call__\n    return await self.call(**values)\n  File \"/root/Projects/Kori-Bot/Kori-bot/./src/plugins/russian/__init__.py\", line 179, in _\n    if bullet_num < 0 or bullet_num > 6:\nTypeError: '<' not supported between instances of 'Message' and 'int'\n"
}